Workbook

Sheet 总览
A1: SUN SMART · CAPEX/OPEX 总览
B3: 货币单位：马来西亚令吉 (RM) | 所有数字最终来源：「关键假设」表
B5: 一次性资本支出 CAPEX
B6: CAPEX 总计（含现金储备） | C6: ='CAPEX 开店资本支出'!E68 -> 89462.5
B8: 每月营运支出 OPEX
B9: 每月 OPEX 总计 | C9: ='OPEX 每月营运支出'!C55 -> 9285
B10: 建议现金储备（2.5个月） | C10: ='OPEX 每月营运支出'!C56 -> 23212.5
B12: 总启动资金需求
B13: CAPEX 总计（已含现金储备） | C13: ='CAPEX 开店资本支出'!E68 -> 89462.5
B14: 对比 RM50,000-100,000 预算区间 | C14: =IF(C13<='关键假设'!C4,"低于下限，资金充裕",IF(C13<='关键假设'!C5,"落在预算区间内","超出预算上限，需调整假设或增资")) -> 落在预算区间内
B17: 12个月预测摘要
B18: 12个月总营收 | C18: ='12个月现金流预测'!N10 -> 890549.85
B19: 12个月净利润合计 | C19: ='12个月现金流预测'!N15 -> 19949.409
B20: 第12月末累计净现金流 | C20: ='12个月现金流预测'!M16 -> 19949.409
B22: 提示：本表所有黄色输入格集中在「关键假设」「CAPEX」「OPEX」三张表，改完后回到本页查看总览是否仍落在预算区间内。

Sheet 使用说明
A1: SUN SMART · CAPEX / OPEX 财务模型
B3: 本表根据《Project A OS · SUN SMART 经营操作系统 Master Document V0.7》第1-3、5、6、8章及 Decision Log 整理而成，用于补上文件中标注「第6章财务预算 待完成」的缺口。
B5: ● 黄色底色的格子：= 可编辑的假设/输入值。拿到真实报价后，直接改这些格子，其余公式会自动重算。
B6: ● 白色/灰色格子：= 公式自动计算，不需要手动改。
B7: ● CAPEX 一次性资本支出：= 开店前一次性投入的钱：押金、装修、设备、首批库存、系统开办费等。
B8: ● OPEX 每月营运支出：= 开店后每个月固定要付的钱：租金、工资、水电、支付手续费等。
B9: ● 现金流与损益预测：= 未来12个月的营收、毛利、费用、净现金流预测，含盈亏平衡点估算。
B10: ● 关键假设：= 集中列出所有关键假设（毛利率、坪效、人流转化率等），方便日后调整重跑，其余表格全部引用这张表。
B12: 使用步骤：
B13: 1. 先在「关键假设」表填入你已经拿到的真实数字（租金、供应商报价等），没拿到的先保留文件里的估算值。
B14: 2. 「CAPEX 开店资本支出」和「OPEX 每月营运支出」会自动引用「关键假设」的数字，也可以直接在两张表里覆盖个别项目。
B15: 3. 「12个月现金流预测」会自动汇总，用来判断 RM50,000-100,000 的启动资金是否足够撑过 Decision Log #024 要求的『连续三个月盈利+正现金流』验证期。
B16: 4. 每次拿到新报价（例如商场 Level B 租金、供应商 Level B 价格）就回来更新对应格子，保持这份表是唯一 Master 财务文件，呼应文件 10.2 的 Decision Log #026 原则。

Sheet 关键假设
A1: 关键假设 Key Assumptions（黄色=可编辑，其余表格全部引用这里）
B3: 启动预算与开业
B4: 启动预算下限 | C4: 50000 | D4: 文件 3.5 / Decision Log #018：RM50,000-100,000
B5: 启动预算上限 | C5: 100000
B7: 收入结构假设 (文件 2.3 / Decision Log #005)
B8: 新机收入占比 | C8: 0.45
B9: 二手机收入占比 | C9: 0.45
B10: 配件收入占比 | C10: 0.1
B12: 毛利率假设 (文件 2.4 / Decision Log #006)
B13: 新机毛利率 | C13: 0.025 | D13: 文件区间 2%-3%，取中间值
B14: 二手机毛利率 | C14: 0.25
B15: 配件毛利率 | C15: 0.4 | D15: 文件区间 30%-50%，取中间值，待供应商报价验证
B17: 库存资金分配 (文件 3.6 / Decision Log #008)
B18: 新机库存占比 | C18: 0.7
B19: 二手机库存占比 | C19: 0.2
B20: 配件库存占比 | C20: 0.1
B21: 首批库存总预算 | C21: 35000 | D21: 建议不超过启动预算的50-60%，分批采购，见文件3.6.4
B23: 销售规模假设（开业首月，可调整，月2起按增长率递增）
B24: 月均手机销售台数 | C24: 40 | D24: 0→1阶段保守假设，建议用首月实际数据校正
B25: 平均每台手机售价 | C25: 1400 | D25: 文件产品定位 RM500-3000 区间的中位数附近
B26: 配件月均订单数 | C26: 150
B27: 配件平均客单价 | C27: 45
B28: 月销量环比增长率 | C28: 0.03 | D28: 假设口碑与线上引流带动缓慢增长
B30: 支付渠道占比与手续费假设 (文件 5.6)
B31: 现金转账占比 | C31: 0.45 | D31: 无手续费
B32: DuitNow QR占比 | C32: 0.2
B33: 信用卡占比 | C33: 0.15
B34: PayLater占比 | C34: 0.2 | D34: 文件区间3-6%取中间偏高
B35: DuitNow QR费率 | C35: 0.01
B36: 信用卡费率 | C36: 0.015
B37: PayLater费率 | C37: 0.045
B39: 人员假设 (文件 2.14)
B40: 员工人数 | C40: 1 | D40: 开业初期1名销售员工
B41: 员工基本工资 | C41: 2000
B42: 雇主EPF SOCSO EIS比例 | C42: 0.13 | D42: 约13%
B43: 销售佣金占毛利比例 | C43: 0.03 | D43: 假设值，需与员工另行约定

Sheet CAPEX 开店资本支出
A1: CAPEX · 开店一次性资本支出（对应文件第3章 Checklist）
B3: 1. 商场租赁 一次性费用 (文件 3.4)
B4: 项目 | C4: 数量 | D4: 单价 (RM) | E4: 小计 (RM) | F4: 备注
B5: 租金押金（一般2-3个月租金） | C5: 1 | D5: 6000 | E5: =C5*D5 -> 6000 | F5: 待Level B报价确认，见文件7.6商场询价问题清单
B6: 水电押金 | C6: 1 | D6: 500 | E6: =C6*D6 -> 500
B7: 装修押金 | C7: 1 | D7: 1000 | E7: =C7*D7 -> 1000
B8: 招牌申请费/图纸审批费 | C8: 1 | D8: 800 | E8: =C8*D8 -> 800
B9: 律师费/印花税（租约） | C9: 1 | D9: 500 | E9: =C9*D9 -> 500
B10: 小计：1. 商场租赁 一次性费用 (文件 3.4) | E10: =SUM(E5:E9) -> 8800
B12: 2. 装修工程 (文件 3.8)
B13: 项目 | C13: 数量 | D13: 单价 (RM) | E13: 小计 (RM) | F13: 备注
B14: 展示柜（可移动/可重复使用款） | C14: 3 | D14: 800 | E14: =C14*D14 -> 2400 | F14: 文件强调优先可移动、未来可搬走
B15: 柜台/收银台 | C15: 1 | D15: 1200 | E15: =C15*D15 -> 1200
B16: 招牌制作与安装 | C16: 1 | D16: 2500 | E16: =C16*D16 -> 2500
B17: 灯光工程 | C17: 1 | D17: 1000 | E17: =C17*D17 -> 1000
B18: 电源/网络布线 | C18: 1 | D18: 800 | E18: =C18*D18 -> 800
B19: 基础油漆与地板整理 | C19: 1 | D19: 1500 | E19: =C19*D19 -> 1500
B20: 装修其他杂项 | C20: 1 | D20: 1000 | E20: =C20*D20 -> 1000
B21: 小计：2. 装修工程 (文件 3.8) | E21: =SUM(E14:E20) -> 10400
B23: 3. 店铺设备 (文件 3.9)
B24: 项目 | C24: 数量 | D24: 单价 (RM) | E24: 小计 (RM) | F24: 备注
B25: CCTV 系统 | C25: 1 | D25: 900 | E25: =C25*D25 -> 900
B26: 电脑/Laptop | C26: 1 | D26: 2200 | E26: =C26*D26 -> 2200
B27: 打印机 | C27: 1 | D27: 400 | E27: =C27*D27 -> 400
B28: Cash Drawer 收银箱 | C28: 1 | D28: 250 | E28: =C28*D28 -> 250
B29: Wi-Fi 路由器 | C29: 1 | D29: 200 | E29: =C29*D29 -> 200
B30: POS/条码扫描器（如采用） | C30: 1 | D30: 600 | E30: =C30*D30 -> 600 | F30: 文件4.4：第一阶段用Google Sheets，POS延后，此项可为0
B31: 手机防盗展示器/小型保险箱 | C31: 1 | D31: 500 | E31: =C31*D31 -> 500
B32: 灭火器/UPS等安全设备 | C32: 1 | D32: 300 | E32: =C32*D32 -> 300
B33: 包装袋/收据本/标签机等开业物料 | C33: 1 | D33: 500 | E33: =C33*D33 -> 500
B34: 小计：3. 店铺设备 (文件 3.9) | E34: =SUM(E25:E33) -> 5850
B36: 4. 支付与系统开办费 (文件 3.10, 5.6)
B37: 项目 | C37: 数量 | D37: 单价 (RM) | E37: 小计 (RM) | F37: 备注
B38: DuitNow QR 申请/开通费 | C38: 1 | D38: 0 | E38: =C38*D38 -> 0 | F38: 通常免费，待Level B确认
B39: 信用卡终端机 Setup Fee | C39: 1 | D39: 300 | E39: =C39*D39 -> 300 | F39: 待HitPay/Revenue Monster报价，见文件5.8
B40: PayLater 平台 Setup Fee | C40: 1 | D40: 300 | E40: =C40*D40 -> 300
B41: WhatsApp Business 设置（人力工时，非现金支出可填0） | C41: 1 | D41: 0 | E41: =C41*D41 -> 0
B42: 自建网站建置费 | C42: 1 | D42: 3000 | E42: =C42*D42 -> 3000 | F42: 文件3.11.2：如短期内无法完成付款功能，可先用WhatsApp接单
B43: 小计：4. 支付与系统开办费 (文件 3.10, 5.6) | E43: =SUM(E38:E42) -> 3600
B45: 5. 公司与合规开办费 (呼应待完成的第9章 法律与文件)
...

Sheet OPEX 每月营运支出
A1: OPEX · 每月营运固定/变动支出（对应文件2.16核心成本结构）
B3: 1. 场地相关 (文件 3.4)
B4: 项目 | C4: 每月金额 (RM) | D4: 备注
B5: 商场基本租金 | C5: 3500 | D5: 待商场Level B报价，见文件7.9联系清单
B6: 管理费/推广费 | C6: 400
B7: 水电费 | C7: 500
B8: 冷气费（如另计） | C8: 200
B9: 网络/通讯费 | C9: 150
B10: 垃圾处理费/其他杂费 | C10: 100
B11: 小计：1. 场地相关 (文件 3.4) | C11: =SUM(C5:C10) -> 4850
B13: 2. 人员成本 (文件 2.16 / 自动引用关键假设)
B14: 项目 | C14: 每月金额 (RM) | D14: 备注
B15: 员工基本工资 | C15: ='关键假设'!C41 -> 2000 | D15: 引用关键假设表·员工基本工资
B16: EPF/SOCSO/EIS 雇主部分 | C16: ='关键假设'!C41*'关键假设'!C42 -> 260 | D16: 计算式：工资 × 雇主负担比例
B17: 销售佣金（估算，实际见现金流预测表按毛利联动） | C17: 300 | D17: 初期估算值，待首月实际毛利数据校正
B18: 小计：2. 人员成本 (文件 2.16 / 自动引用关键假设) | C18: =SUM(C15:C17) -> 2560
B20: 3. 支付渠道手续费（变动成本，随营收自动计算）
B21: 项目 | C21: 每月金额 (RM) | D21: 备注
B22: 说明：手续费为变动成本，已在「12个月现金流预测」按渠道占比与费率自动计算，此处填0避免重复计算 | C22: 0 | D22: 如需查看月度手续费金额，见「12个月现金流预测」表
B23: 小计：3. 支付渠道手续费（变动成本，随营收自动计算） | C23: =SUM(C22:C22) -> 0
B25: 4. 营销与获客 (文件 2.13, 3.15)
B26: 项目 | C26: 每月金额 (RM) | D26: 备注
B27: Facebook 广告 | C27: 500
B28: TikTok 内容/广告 | C28: 300
B29: 开业/促销物料（首3个月后转为常态小额预算） | C29: 200
B30: 小计：4. 营销与获客 (文件 2.13, 3.15) | C30: =SUM(C27:C29) -> 1000
B32: 5. 系统与订阅 (文件 4.3-4.4, 3.11)
B33: 项目 | C33: 每月金额 (RM) | D33: 备注
B34: Google Sheets（官方库存/记录方案，免费-约RM300/年按月折算） | C34: 25 | D34: 文件4.4：Decision Log #007已定为免费/低成本方案
B35: 网站维护/域名/主机 | C35: 100
B36: WhatsApp Business（免费，如用第三方工具另计） | C36: 0
B37: 小计：5. 系统与订阅 (文件 4.3-4.4, 3.11) | C37: =SUM(C34:C36) -> 125
B39: 6. 售后与风险准备 (文件 2.12, 3.13, 3.14 / 呼应第9章法律缺口)
B40: 项目 | C40: 每月金额 (RM) | D40: 备注
B41: 维修/售后处理准备金 | C41: 300 | D41: 对应外部维修商合作费用及非原厂保修处理
B42: 保险分摊（如决定购买，见文件3.14） | C42: 0 | D42: 暂不购买，先研究；决定后按年保费/12填入
B43: 坏账/退换损耗准备（约营收0.5%，估算值） | C43: 150
B44: 小计：6. 售后与风险准备 (文件 2.12, 3.13, 3.14 / 呼应第9章法律缺口) | C44: =SUM(C41:C43) -> 450
B46: 7. 其他行政 (呼应待完成第9章法律与文件)
B47: 项目 | C47: 每月金额 (RM) | D47: 备注
...

Sheet 12个月现金流预测
A1: 12个月现金流与损益预测（自动引用「关键假设」「OPEX」，月2起按增长率递增）
A3: 项目 | B3: 第1月 | C3: 第2月 | D3: 第3月 | E3: 第4月 | F3: 第5月 | G3: 第6月 | H3: 第7月 | I3: 第8月 | J3: 第9月 | K3: 第10月 | L3: 第11月 | M3: 第12月 | N3: 12月合计
A4: 手机销量（台，月2起按增长率递增） | B4: ='关键假设'!C24 -> 40 | C4: =B4*(1+'关键假设'!C28) -> 41.2 | D4: =C4*(1+'关键假设'!C28) -> 42.436 | E4: =D4*(1+'关键假设'!C28) -> 43.70908 | F4: =E4*(1+'关键假设'!C28) -> 45.020352 | G4: =F4*(1+'关键假设'!C28) -> 46.370963 | H4: =G4*(1+'关键假设'!C28) -> 47.762092 | I4: =H4*(1+'关键假设'!C28) -> 49.194955 | J4: =I4*(1+'关键假设'!C28) -> 50.670803 | K4: =J4*(1+'关键假设'!C28) -> 52.190927 | L4: =K4*(1+'关键假设'!C28) -> 53.756655 | M4: =L4*(1+'关键假设'!C28) -> 55.369355 | N4: =SUM(B4:M4) -> 567.68118
A5: 平均单台售价 (RM) | B5: ='关键假设'!C25 -> 1400 | C5: ='关键假设'!C25 -> 1400 | D5: ='关键假设'!C25 -> 1400 | E5: ='关键假设'!C25 -> 1400 | F5: ='关键假设'!C25 -> 1400 | G5: ='关键假设'!C25 -> 1400 | H5: ='关键假设'!C25 -> 1400 | I5: ='关键假设'!C25 -> 1400 | J5: ='关键假设'!C25 -> 1400 | K5: ='关键假设'!C25 -> 1400 | L5: ='关键假设'!C25 -> 1400 | M5: ='关键假设'!C25 -> 1400
A6: 手机销售额 (RM) | B6: =B4*B5 -> 56000 | C6: =C4*C5 -> 57680 | D6: =D4*D5 -> 59410.4 | E6: =E4*E5 -> 61192.712 | F6: =F4*F5 -> 63028.493 | G6: =G4*G5 -> 64919.348 | H6: =H4*H5 -> 66866.929 | I6: =I4*I5 -> 68872.936 | ... M6: =M4*M5 -> 77517.097 | N6: =SUM(B6:M6) -> 794753.66
A7: 配件订单数 | B7: ='关键假设'!C26 -> 150 | C7: =B7*(1+'关键假设'!C28) -> 154.5 | D7: =C7*(1+'关键假设'!C28) -> 159.135 | E7: =D7*(1+'关键假设'!C28) -> 163.90905 | F7: =E7*(1+'关键假设'!C28) -> 168.82632 | G7: =F7*(1+'关键假设'!C28) -> 173.89111 | H7: =G7*(1+'关键假设'!C28) -> 179.10784 | I7: =H7*(1+'关键假设'!C28) -> 184.48108 | J7: =I7*(1+'关键假设'!C28) -> 190.01551 | K7: =J7*(1+'关键假设'!C28) -> 195.71598 | L7: =K7*(1+'关键假设'!C28) -> 201.58746 | M7: =L7*(1+'关键假设'!C28) -> 207.63508 | N7: =SUM(B7:M7) -> 2128.8044
A8: 配件平均客单价 (RM) | B8: ='关键假设'!C27 -> 45 | C8: ='关键假设'!C27 -> 45 | D8: ='关键假设'!C27 -> 45 | E8: ='关键假设'!C27 -> 45 | F8: ='关键假设'!C27 -> 45 | G8: ='关键假设'!C27 -> 45 | H8: ='关键假设'!C27 -> 45 | I8: ='关键假设'!C27 -> 45 | J8: ='关键假设'!C27 -> 45 | K8: ='关键假设'!C27 -> 45 | L8: ='关键假设'!C27 -> 45 | M8: ='关键假设'!C27 -> 45
A9: 配件销售额 (RM) | B9: =B7*B8 -> 6750 | C9: =C7*C8 -> 6952.5 | D9: =D7*D8 -> 7161.075 | E9: =E7*E8 -> 7375.9073 | F9: =F7*F8 -> 7597.1845 | G9: =G7*G8 -> 7825.1 | H9: =H7*H8 -> 8059.853 | I9: =I7*I8 -> 8301.6486 | ... M9: =M7*M8 -> 9343.5786 | N9: =SUM(B9:M9) -> 95796.2
A10: 总营收 (RM) | B10: =B6+B9 -> 62750 | C10: =C6+C9 -> 64632.5 | D10: =D6+D9 -> 66571.475 | E10: =E6+E9 -> 68568.619 | F10: =F6+F9 -> 70625.678 | G10: =G6+G9 -> 72744.448 | H10: =H6+H9 -> 74926.782 | I10: =I6+I9 -> 77174.585 | ... M10: =M6+M9 -> 86860.675 | N10: =SUM(B10:M10) -> 890549.85
A11: 估算毛利 (RM) 新机/二手机/配件加权 | B11: =(B6*(('关键假设'!C8/('关键假设'!C8+'关键假设'!C9))*'关键假设'!C13+('关键假设'!C9/('关键假设'!C8+'关键假设'!C9))*'关键假设'!C14))+(B9*'关键假设'!C15) -> 10400 | C11: =(C6*(('关键假设'!C8/('关键假设'!C8+'关键假设'!C9))*'关键假设'!C13+('关键假设'!C9/('关键假设'!C8+'关键假设'!C9))*'关键假设'!C14))+(C9*'关键假设'!C15) -> 10712 | D11: =(D6*(('关键假设'!C8/('关键假设'!C8+'关键假设'!C9))*'关键假设'!C13+('关键假设'!C9/('关键假设'!C8+'关键假设'!C9))*'关键假设'!C14))+(D9*'关键假设'!C15) -> 11033.36 | E11: =(E6*(('关键假设'!C8/('关键假设'!C8+'关键假设'!C9))*'关键假设'!C13+('关键假设'!C9/('关键假设'!C8+'关键假设'!C9))*'关键假设'!C14))+(E9*'关键假设'!C15) -> 11364.361 | F11: =(F6*(('关键假设'!C8/('关键假设'!C8+'关键假设'!C9))*'关键假设'!C13+('关键假设'!C9/('关键假设'!C8+'关键假设'!C9))*'关键假设'!C14))+(F9*'关键假设'!C15) -> 11705.292 | G11: =(G6*(('关键假设'!C8/('关键假设'!C8+'关键假设'!C9))*'关键假设'!C13+('关键假设'!C9/('关键假设'!C8+'关键假设'!C9))*'关键假设'!C14))+(G9*'关键假设'!C15) -> 12056.45 | H11: =(H6*(('关键假设'!C8/('关键假设'!C8+'关键假设'!C9))*'关键假设'!C13+('关键假设'!C9/('关键假设'!C8+'关键假设'!C9))*'关键假设'!C14))+(H9*'关键假设'!C15) -> 12418.144 | I11: =(I6*(('关键假设'!C8/('关键假设'!C8+'关键假设'!C9))*'关键假设'!C13+('关键假设'!C9/('关键假设'!C8+'关键假设'!C9))*'关键假设'!C14))+(I9*'关键假设'!C15) -> 12790.688 | J11: =(J6*(('关键假设'!C8/('关键假设'!C8+'关键假设'!C9))*'关键假设'!C13+('关键假设'!C9/('关键假设'!C8+'关键假设'!C9))*'关键假设'!C14))+(J9*'关键假设'!C15) -> 13174.409 | K11: =(K6*(('关键假设'!C8/('关键假设'!C8+'关键假设'!C9))*'关键假设'!C13+('关键假设'!C9/('关键假设'!C8+'关键假设'!C9))*'关键假设'!C14))+(K9*'关键假设'!C15) -> 13569.641 | L11: =(L6*(('关键假设'!C8/('关键假设'!C8+'关键假设'!C9))*'关键假设'!C13+('关键假设'!C9/('关键假设'!C8+'关键假设'!C9))*'关键假设'!C14))+(L9*'关键假设'!C15) -> 13976.73 | M11: =(M6*(('关键假设'!C8/('关键假设'!C8+'关键假设'!C9))*'关键假设'!C13+('关键假设'!C9/('关键假设'!C8+'关键假设'!C9))*'关键假设'!C14))+(M9*'关键假设'!C15) -> 14396.032 | N11: =SUM(B11:M11) -> 147597.11
A12: 支付手续费 (RM) | B12: =B10*('关键假设'!C32*'关键假设'!C35+'关键假设'!C33*'关键假设'!C36+'关键假设'!C34*'关键假设'!C37) -> 831.4375 | C12: =C10*('关键假设'!C32*'关键假设'!C35+'关键假设'!C33*'关键假设'!C36+'关键假设'!C34*'关键假设'!C37) -> 856.38063 | D12: =D10*('关键假设'!C32*'关键假设'!C35+'关键假设'!C33*'关键假设'!C36+'关键假设'!C34*'关键假设'!C37) -> 882.07204 | E12: =E10*('关键假设'!C32*'关键假设'!C35+'关键假设'!C33*'关键假设'!C36+'关键假设'!C34*'关键假设'!C37) -> 908.53421 | F12: =F10*('关键假设'!C32*'关键假设'!C35+'关键假设'!C33*'关键假设'!C36+'关键假设'!C34*'关键假设'!C37) -> 935.79023 | G12: =G10*('关键假设'!C32*'关键假设'!C35+'关键假设'!C33*'关键假设'!C36+'关键假设'!C34*'关键假设'!C37) -> 963.86394 | H12: =H10*('关键假设'!C32*'关键假设'!C35+'关键假设'!C33*'关键假设'!C36+'关键假设'!C34*'关键假设'!C37) -> 992.77986 | I12: =I10*('关键假设'!C32*'关键假设'!C35+'关键假设'!C33*'关键假设'!C36+'关键假设'!C34*'关键假设'!C37) -> 1022.5633 | J12: =J10*('关键假设'!C32*'关键假设'!C35+'关键假设'!C33*'关键假设'!C36+'关键假设'!C34*'关键假设'!C37) -> 1053.2401 | K12: =K10*('关键假设'!C32*'关键假设'!C35+'关键假设'!C33*'关键假设'!C36+'关键假设'!C34*'关键假设'!C37) -> 1084.8374 | L12: =L10*('关键假设'!C32*'关键假设'!C35+'关键假设'!C33*'关键假设'!C36+'关键假设'!C34*'关键假设'!C37) -> 1117.3825 | M12: =M10*('关键假设'!C32*'关键假设'!C35+'关键假设'!C33*'关键假设'!C36+'关键假设'!C34*'关键假设'!C37) -> 1150.9039 | N12: =SUM(B12:M12) -> 11799.786
A13: 每月固定营运支出 OPEX (RM) | B13: ='OPEX 每月营运支出'!C55 -> 9285 | C13: ='OPEX 每月营运支出'!C55 -> 9285 | D13: ='OPEX 每月营运支出'!C55 -> 9285 | E13: ='OPEX 每月营运支出'!C55 -> 9285 | F13: ='OPEX 每月营运支出'!C55 -> 9285 | G13: ='OPEX 每月营运支出'!C55 -> 9285 | H13: ='OPEX 每月营运支出'!C55 -> 9285 | I13: ='OPEX 每月营运支出'!C55 -> 9285 | J13: ='OPEX 每月营运支出'!C55 -> 9285 | K13: ='OPEX 每月营运支出'!C55 -> 9285 | L13: ='OPEX 每月营运支出'!C55 -> 9285 | M13: ='OPEX 每月营运支出'!C55 -> 9285 | N13: =SUM(B13:M13) -> 111420
A14: 销售佣金 (毛利的比例) | B14: =B11*'关键假设'!C43 -> 312 | C14: =C11*'关键假设'!C43 -> 321.36 | D14: =D11*'关键假设'!C43 -> 331.0008 | E14: =E11*'关键假设'!C43 -> 340.93082 | F14: =F11*'关键假设'!C43 -> 351.15875 | G14: =G11*'关键假设'!C43 -> 361.69351 | H14: =H11*'关键假设'!C43 -> 372.54432 | I14: =I11*'关键假设'!C43 -> 383.72065 | J14: =J11*'关键假设'!C43 -> 395.23227 | K14: =K11*'关键假设'!C43 -> 407.08923 | L14: =L11*'关键假设'!C43 -> 419.30191 | M14: =M11*'关键假设'!C43 -> 431.88097 | N14: =SUM(B14:M14) -> 4427.9132
A15: 净利润 (RM) = 毛利 − 手续费 − OPEX − 佣金 | B15: =B11-B12-B13-B14 -> -28.4375 | C15: =C11-C12-C13-C14 -> 249.25938 | D15: =D11-D12-D13-D14 -> 535.28716 | E15: =E11-E12-E13-E14 -> 829.89577 | F15: =F11-F12-F13-F14 -> 1133.3426 | G15: =G11-G12-G13-G14 -> 1445.8929 | H15: =H11-H12-H13-H14 -> 1767.8197 | I15: =I11-I12-I13-I14 -> 2099.4043 | ... M15: =M11-M12-M13-M14 -> 3528.2473 | N15: =SUM(B15:M15) -> 19949.409
A16: 累计净现金流 (RM，起点为0，未计CAPEX) | B16: =B15 -> -28.4375 | C16: =B16+C15 -> 220.82188 | D16: =C16+D15 -> 756.10903 | E16: =D16+E15 -> 1586.0048 | F16: =E16+F15 -> 2719.3474 | G16: =F16+G15 -> 4165.2404 | H16: =G16+H15 -> 5933.0601 | I16: =H16+I15 -> 8032.4644 | J16: =I16+J15 -> 10473.401 | ... M16: =L16+M15 -> 19949.409
A18: Decision Log #024 验证标准：连续3个月净利润>0 且累计净现金流为正
