Workbook

Sheet Summary
A1: SUN SMART · CAPEX/OPEX Summary
B3: Currency: Malaysian Ringgit (RM) | Single source of truth for all figures: "Key Assumptions" sheet
B5: One-off Capital Expenditure (CAPEX)
B6: CAPEX total (incl. cash reserve) | C6: ='CAPEX Startup Capex'!E68
B8: Monthly Operating Expenses (OPEX)
B9: Monthly OPEX total | C9: ='OPEX Monthly Opex'!C55
B10: Recommended cash reserve (2.5 months) | C10: ='OPEX Monthly Opex'!C56
B12: Total Startup Funding Requirement
B13: CAPEX total (already incl. cash reserve) | C13: ='CAPEX Startup Capex'!E68
B14: vs. RM50,000-100,000 budget range | C14: =IF(C13<='Key Assumptions'!C4,"Below the lower bound, ample budget",IF(C13<='Key Assumptions'!C5,"Within the budget range","Exceeds the upper bound, adjust assumptions or raise more capital"))
B17: 12-Month Forecast Summary
B18: 12-month total revenue | C18: ='12-Month Cash Flow Forecast'!N10
B19: 12-month total net profit | C19: ='12-Month Cash Flow Forecast'!N15
B20: Cumulative net cash flow at end of Month 12 | C20: ='12-Month Cash Flow Forecast'!M16
B22: Tip: every yellow input cell lives on the "Key Assumptions", "CAPEX" and "OPEX" sheets. After editing, come back to this Summary page to check you're still within budget.

Sheet Instructions
A1: SUN SMART · CAPEX / OPEX Financial Model
B3: Built from the Project A OS · SUN SMART Master Document V0.7 (Chapters 1-3, 5, 6, 8 and the Decision Log). Fills the gap flagged in the document as "Chapter 6 - Financial Budget - Not yet completed".
B5: * Yellow cells: Editable assumptions/inputs. Once you have real quotes, edit these cells and every total recalculates automatically.
B6: * White/grey cells: Calculated automatically by formula - do not need to be edited.
B7: * CAPEX - Startup Capital Expenditure: One-off costs before opening: deposits, renovation, equipment, initial inventory, setup fees.
B8: * OPEX - Monthly Operating Expenses: Recurring monthly costs after opening: rent, salary, utilities, payment fees, etc.
B9: * Cash Flow & P&L Forecast: 12-month projection of revenue, gross margin, expenses and net cash flow, including a break-even indicator.
B10: * Key Assumptions: All key assumptions (margins, revenue mix, footfall conversion, etc.) in one place; every other sheet references this sheet.
B12: How to use this workbook:
B13: 1. Start by entering any real numbers you already have (rent quotes, supplier prices, etc.) into the "Key Assumptions" sheet. Where you don't have real numbers yet, keep the estimates from the master document.
B14: 2. "CAPEX - Startup Capital Expenditure" and "OPEX - Monthly Operating Expenses" automatically reference the Key Assumptions sheet, but you can also override individual line items directly on those two sheets.
B15: 3. "12-Month Cash Flow Forecast" rolls everything up automatically, so you can check whether the RM50,000-100,000 startup budget is enough to survive the "3 consecutive months of profit + positive cash flow" validation bar set in Decision Log #024.
B16: 4. Whenever you get a new quote (e.g. mall Level B rental, supplier Level B pricing), come back and update the corresponding cell so this stays the single master financial file, in line with Decision Log #026 (Section 10.2) of the master document.

Sheet Key Assumptions
A1: Key Assumptions (Yellow = editable; every other sheet references this sheet)
B3: Startup Budget & Launch
B4: Startup budget - lower bound | C4: 50000 | D4: Doc §3.5 / Decision Log #018: RM50,000-100,000
B5: Startup budget - upper bound | C5: 100000
B7: Revenue Mix Assumptions (Doc §2.3 / Decision Log #005)
B8: New phone revenue share | C8: 0.45
B9: Used phone revenue share | C9: 0.45
B10: Accessories revenue share | C10: 0.1
B12: Gross Margin Assumptions (Doc §2.4 / Decision Log #006)
B13: New phone gross margin | C13: 0.025 | D13: Doc range 2%-3%, midpoint used
B14: Used phone gross margin | C14: 0.25
B15: Accessories gross margin | C15: 0.4 | D15: Doc range 30%-50%, midpoint used, pending supplier quotes
B17: Inventory Capital Allocation (Doc §3.6 / Decision Log #008)
B18: New phone inventory share | C18: 0.7
B19: Used phone inventory share | C19: 0.2
B20: Accessories inventory share | C20: 0.1
B21: Initial inventory budget total | C21: 35000 | D21: Recommended to not exceed 50-60% of startup budget; buy in batches, see Doc §3.6.4
B23: Sales Volume Assumptions (Month 1 baseline; Month 2+ grows at monthly growth rate)
B24: Avg monthly phone units sold | C24: 40 | D24: Conservative 0-to-1 stage assumption; calibrate with real Month 1 data
B25: Avg selling price per phone | C25: 1400 | D25: Near the midpoint of the doc's RM500-3000 product range
B26: Avg monthly accessory orders | C26: 150
B27: Avg accessory order value | C27: 45
B28: Month-over-month sales growth rate | C28: 0.03 | D28: Assumes slow growth driven by word-of-mouth and online traffic
B30: Payment Channel Mix & Fee Assumptions (Doc §5.6)
B31: Cash / bank transfer share | C31: 0.45 | D31: No fee
B32: DuitNow QR share | C32: 0.2
B33: Credit card share | C33: 0.15
B34: PayLater share | C34: 0.2 | D34: Doc range 3-6%, upper-middle used
B35: DuitNow QR fee rate | C35: 0.01
B36: Credit card fee rate | C36: 0.015
B37: PayLater fee rate | C37: 0.045
B39: Staffing Assumptions (Doc §2.14)
B40: Number of staff | C40: 1 | D40: 1 sales staff at launch
B41: Staff base salary | C41: 2000
B42: Employer EPF SOCSO EIS rate | C42: 0.13 | D42: Approx. 13%
B43: Sales commission pct of gross margin | C43: 0.03 | D43: Assumed value, to be agreed with staff separately

Sheet CAPEX Startup Capex
A1: CAPEX · Startup Capital Expenditure (maps to Doc Chapter 3 Checklist)
B3: 1. Mall Lease - One-off Costs (Doc §3.4)
B4: Item | C4: Qty | D4: Unit Cost (RM) | E4: Subtotal (RM) | F4: Note
B5: Rental deposit (typically 2-3 months' rent) | C5: 1 | D5: 6000 | E5: =C5*D5 | F5: Pending mall Level B quote, see Doc §7.6 questions checklist
B6: Utilities deposit | C6: 1 | D6: 500 | E6: =C6*D6
B7: Renovation deposit | C7: 1 | D7: 1000 | E7: =C7*D7
B8: Signboard application / drawing approval fee | C8: 1 | D8: 800 | E8: =C8*D8
B9: Legal fee / stamp duty (tenancy agreement) | C9: 1 | D9: 500 | E9: =C9*D9
B10: Subtotal: 1. Mall Lease - One-off Costs (Doc §3.4) | E10: =SUM(E5:E9)
B12: 2. Renovation (Doc §3.8)
B13: Item | C13: Qty | D13: Unit Cost (RM) | E13: Subtotal (RM) | F13: Note
B14: Display cabinets (movable / reusable) | C14: 3 | D14: 800 | E14: =C14*D14 | F14: Doc emphasises movable, reusable fixtures for future relocation
B15: Counter / cashier station | C15: 1 | D15: 1200 | E15: =C15*D15
B16: Signboard production & installation | C16: 1 | D16: 2500 | E16: =C16*D16
B17: Lighting works | C17: 1 | D17: 1000 | E17: =C17*D17
B18: Power / network wiring | C18: 1 | D18: 800 | E18: =C18*D18
B19: Basic paint and flooring touch-up | C19: 1 | D19: 1500 | E19: =C19*D19
B20: Renovation - other misc | C20: 1 | D20: 1000 | E20: =C20*D20
B21: Subtotal: 2. Renovation (Doc §3.8) | E21: =SUM(E14:E20)
B23: 3. Shop Equipment (Doc §3.9)
B24: Item | C24: Qty | D24: Unit Cost (RM) | E24: Subtotal (RM) | F24: Note
B25: CCTV system | C25: 1 | D25: 900 | E25: =C25*D25
B26: Computer / laptop | C26: 1 | D26: 2200 | E26: =C26*D26
B27: Printer | C27: 1 | D27: 400 | E27: =C27*D27
B28: Cash drawer | C28: 1 | D28: 250 | E28: =C28*D28
B29: Wi-Fi router | C29: 1 | D29: 200 | E29: =C29*D29
B30: POS / barcode scanner (if adopted) | C30: 1 | D30: 600 | E30: =C30*D30 | F30: Doc §4.4: Phase 1 uses Google Sheets, POS deferred - can be 0
B31: Anti-theft display stand / small safe | C31: 1 | D31: 500 | E31: =C31*D31
B32: Fire extinguisher / UPS / other safety equipment | C32: 1 | D32: 300 | E32: =C32*D32
B33: Packaging bags / receipt books / label printer, etc. | C33: 1 | D33: 500 | E33: =C33*D33
B34: Subtotal: 3. Shop Equipment (Doc §3.9) | E34: =SUM(E25:E33)
B36: 4. Payments & Systems Setup (Doc §3.10, 5.6)
B37: Item | C37: Qty | D37: Unit Cost (RM) | E37: Subtotal (RM) | F37: Note
B38: DuitNow QR application / activation fee | C38: 1 | D38: 0 | E38: =C38*D38 | F38: Usually free, pending Level B confirmation
B39: Credit card terminal setup fee | C39: 1 | D39: 300 | E39: =C39*D39 | F39: Pending HitPay / Revenue Monster quotes, see Doc §5.8
B40: PayLater platform setup fee | C40: 1 | D40: 300 | E40: =C40*D40
B41: WhatsApp Business setup (labour time, can be 0 if no cash cost) | C41: 1 | D41: 0 | E41: =C41*D41
B42: Website build cost | C42: 1 | D42: 3000 | E42: =C42*D42 | F42: Doc §3.11.2: if online payment can't be ready in time, use WhatsApp ordering first
B43: Subtotal: 4. Payments & Systems Setup (Doc §3.10, 5.6) | E43: =SUM(E38:E42)
B45: 5. Company & Compliance Setup (mirrors the not-yet-completed Chapter 9 - Legal & Documentation)
...

Sheet OPEX Monthly Opex
A1: OPEX · Monthly Operating Expenses (maps to Doc §2.16 core cost structure)
B3: 1. Premises (Doc §3.4)
B4: Item | C4: Monthly Amount (RM) | D4: Note
B5: Base mall rent | C5: 3500 | D5: Pending mall Level B quote, see Doc §7.9 contact list
B6: Management / promotion fee | C6: 400
B7: Utilities (electricity/water) | C7: 500
B8: Air-conditioning charge (if billed separately) | C8: 200
B9: Internet / telecom | C9: 150
B10: Refuse collection / other misc fees | C10: 100
B11: Subtotal: 1. Premises (Doc §3.4) | C11: =SUM(C5:C10)
B13: 2. Staffing Costs (Doc §2.16 / auto-linked to Key Assumptions)
B14: Item | C14: Monthly Amount (RM) | D14: Note
B15: Staff base salary | C15: ='Key Assumptions'!C41 | D15: Linked to Key Assumptions - staff base salary
B16: EPF/SOCSO/EIS employer portion | C16: ='Key Assumptions'!C41*'Key Assumptions'!C42 | D16: Formula: salary x employer contribution rate
B17: Sales commission (estimate; actual linked to gross margin in forecast sheet) | C17: 300 | D17: Initial estimate, calibrate with first month's actual gross margin
B18: Subtotal: 2. Staffing Costs (Doc §2.16 / auto-linked to Key Assumptions) | C18: =SUM(C15:C17)
B20: 3. Payment Channel Fees (variable cost, auto-calculated from revenue)
B21: Item | C21: Monthly Amount (RM) | D21: Note
B22: Note: fees are a variable cost, already auto-calculated by channel mix and fee rate in "12-Month Cash Flow Forecast"; kept at 0 here to avoid double-counting | C22: 0 | D22: See the "12-Month Cash Flow Forecast" sheet for the monthly fee amount
B23: Subtotal: 3. Payment Channel Fees (variable cost, auto-calculated from revenue) | C23: =SUM(C22:C22)
B25: 4. Marketing & Customer Acquisition (Doc §2.13, 3.15)
B26: Item | C26: Monthly Amount (RM) | D26: Note
B27: Facebook ads | C27: 500
B28: TikTok content / ads | C28: 300
B29: Launch / promo materials (reverts to a small standing budget after month 3) | C29: 200
B30: Subtotal: 4. Marketing & Customer Acquisition (Doc §2.13, 3.15) | C30: =SUM(C27:C29)
B32: 5. Systems & Subscriptions (Doc §4.3-4.4, 3.11)
B33: Item | C33: Monthly Amount (RM) | D33: Note
B34: Google Sheets (official inventory/records system, free-~RM300/yr pro-rated monthly) | C34: 25 | D34: Doc §4.4: Decision Log #007 confirms the free/low-cost route
B35: Website maintenance / domain / hosting | C35: 100
B36: WhatsApp Business (free; add cost if using a 3rd-party tool) | C36: 0
B37: Subtotal: 5. Systems & Subscriptions (Doc §4.3-4.4, 3.11) | C37: =SUM(C34:C36)
B39: 6. After-sales & Risk Reserve (Doc §2.12, 3.13, 3.14 / mirrors the Chapter 9 legal gap)
B40: Item | C40: Monthly Amount (RM) | D40: Note
B41: Repair / after-sales handling reserve | C41: 300 | D41: For external repair-partner fees and non-warranty repair handling
B42: Insurance allocation (if purchased, see Doc §3.14) | C42: 0 | D42: Not purchasing yet, researching first; fill in annual premium / 12 once decided
B43: Bad debt / return-loss reserve (approx. 0.5% of revenue, estimate) | C43: 150
B44: Subtotal: 6. After-sales & Risk Reserve (Doc §2.12, 3.13, 3.14 / mirrors the Chapter 9 legal gap) | C44: =SUM(C41:C43)
B46: 7. Other Admin (mirrors the not-yet-completed Chapter 9 - Legal & Documentation)
B47: Item | C47: Monthly Amount (RM) | D47: Note
...

Sheet 12-Month Cash Flow Forecast
A1: 12-Month Cash Flow & P&L Forecast (auto-linked to Key Assumptions and OPEX; Month 2+ compounds at the growth rate)
A3: Line Item | B3: Month 1 | C3: Month 2 | D3: Month 3 | E3: Month 4 | F3: Month 5 | G3: Month 6 | H3: Month 7 | I3: Month 8 | J3: Month 9 | K3: Month 10 | L3: Month 11 | M3: Month 12 | N3: 12-Month Total
A4: Phone units sold (compounds from Month 2 at growth rate) | B4: ='Key Assumptions'!C24 | C4: =B4*(1+'Key Assumptions'!C28) | D4: =C4*(1+'Key Assumptions'!C28) | E4: =D4*(1+'Key Assumptions'!C28) | F4: =E4*(1+'Key Assumptions'!C28) | G4: =F4*(1+'Key Assumptions'!C28) | H4: =G4*(1+'Key Assumptions'!C28) | I4: =H4*(1+'Key Assumptions'!C28) | J4: =I4*(1+'Key Assumptions'!C28) | K4: =J4*(1+'Key Assumptions'!C28) | L4: =K4*(1+'Key Assumptions'!C28) | M4: =L4*(1+'Key Assumptions'!C28) | N4: =SUM(B4:M4)
A5: Avg selling price per phone (RM) | B5: ='Key Assumptions'!C25 | C5: ='Key Assumptions'!C25 | D5: ='Key Assumptions'!C25 | E5: ='Key Assumptions'!C25 | F5: ='Key Assumptions'!C25 | G5: ='Key Assumptions'!C25 | H5: ='Key Assumptions'!C25 | I5: ='Key Assumptions'!C25 | J5: ='Key Assumptions'!C25 | K5: ='Key Assumptions'!C25 | L5: ='Key Assumptions'!C25 | M5: ='Key Assumptions'!C25
A6: Phone sales revenue (RM) | B6: =B4*B5 | C6: =C4*C5 | D6: =D4*D5 | E6: =E4*E5 | F6: =F4*F5 | G6: =G4*G5 | H6: =H4*H5 | I6: =I4*I5 | ... M6: =M4*M5 | N6: =SUM(B6:M6)
A7: Accessory orders | B7: ='Key Assumptions'!C26 | C7: =B7*(1+'Key Assumptions'!C28) | D7: =C7*(1+'Key Assumptions'!C28) | E7: =D7*(1+'Key Assumptions'!C28) | F7: =E7*(1+'Key Assumptions'!C28) | G7: =F7*(1+'Key Assumptions'!C28) | H7: =G7*(1+'Key Assumptions'!C28) | I7: =H7*(1+'Key Assumptions'!C28) | J7: =I7*(1+'Key Assumptions'!C28) | K7: =J7*(1+'Key Assumptions'!C28) | L7: =K7*(1+'Key Assumptions'!C28) | M7: =L7*(1+'Key Assumptions'!C28) | N7: =SUM(B7:M7)
A8: Avg accessory order value (RM) | B8: ='Key Assumptions'!C27 | C8: ='Key Assumptions'!C27 | D8: ='Key Assumptions'!C27 | E8: ='Key Assumptions'!C27 | F8: ='Key Assumptions'!C27 | G8: ='Key Assumptions'!C27 | H8: ='Key Assumptions'!C27 | I8: ='Key Assumptions'!C27 | J8: ='Key Assumptions'!C27 | K8: ='Key Assumptions'!C27 | L8: ='Key Assumptions'!C27 | M8: ='Key Assumptions'!C27
A9: Accessories sales revenue (RM) | B9: =B7*B8 | C9: =C7*C8 | D9: =D7*D8 | E9: =E7*E8 | F9: =F7*F8 | G9: =G7*G8 | H9: =H7*H8 | I9: =I7*I8 | ... M9: =M7*M8 | N9: =SUM(B9:M9)
A10: Total revenue (RM) | B10: =B6+B9 | C10: =C6+C9 | D10: =D6+D9 | E10: =E6+E9 | F10: =F6+F9 | G10: =G6+G9 | H10: =H6+H9 | I10: =I6+I9 | ... M10: =M6+M9 | N10: =SUM(B10:M10)
A11: Estimated gross margin (RM) - new/used/accessories blended | B11: =(B6*(('Key Assumptions'!C8/('Key Assumptions'!C8+'Key Assumptions'!C9))*'Key Assumptions'!C13+('Key Assumptions'!C9/('Key Assumptions'!C8+'Key Assumptions'!C9))*'Key Assumptions'!C14))+(B9*'Key Assumptions'!C15) | C11: =(C6*(('Key Assumptions'!C8/('Key Assumptions'!C8+'Key Assumptions'!C9))*'Key Assumptions'!C13+('Key Assumptions'!C9/('Key Assumptions'!C8+'Key Assumptions'!C9))*'Key Assumptions'!C14))+(C9*'Key Assumptions'!C15) | D11: =(D6*(('Key Assumptions'!C8/('Key Assumptions'!C8+'Key Assumptions'!C9))*'Key Assumptions'!C13+('Key Assumptions'!C9/('Key Assumptions'!C8+'Key Assumptions'!C9))*'Key Assumptions'!C14))+(D9*'Key Assumptions'!C15) | E11: =(E6*(('Key Assumptions'!C8/('Key Assumptions'!C8+'Key Assumptions'!C9))*'Key Assumptions'!C13+('Key Assumptions'!C9/('Key Assumptions'!C8+'Key Assumptions'!C9))*'Key Assumptions'!C14))+(E9*'Key Assumptions'!C15) | F11: =(F6*(('Key Assumptions'!C8/('Key Assumptions'!C8+'Key Assumptions'!C9))*'Key Assumptions'!C13+('Key Assumptions'!C9/('Key Assumptions'!C8+'Key Assumptions'!C9))*'Key Assumptions'!C14))+(F9*'Key Assumptions'!C15) | G11: =(G6*(('Key Assumptions'!C8/('Key Assumptions'!C8+'Key Assumptions'!C9))*'Key Assumptions'!C13+('Key Assumptions'!C9/('Key Assumptions'!C8+'Key Assumptions'!C9))*'Key Assumptions'!C14))+(G9*'Key Assumptions'!C15) | H11: =(H6*(('Key Assumptions'!C8/('Key Assumptions'!C8+'Key Assumptions'!C9))*'Key Assumptions'!C13+('Key Assumptions'!C9/('Key Assumptions'!C8+'Key Assumptions'!C9))*'Key Assumptions'!C14))+(H9*'Key Assumptions'!C15) | I11: =(I6*(('Key Assumptions'!C8/('Key Assumptions'!C8+'Key Assumptions'!C9))*'Key Assumptions'!C13+('Key Assumptions'!C9/('Key Assumptions'!C8+'Key Assumptions'!C9))*'Key Assumptions'!C14))+(I9*'Key Assumptions'!C15) | J11: =(J6*(('Key Assumptions'!C8/('Key Assumptions'!C8+'Key Assumptions'!C9))*'Key Assumptions'!C13+('Key Assumptions'!C9/('Key Assumptions'!C8+'Key Assumptions'!C9))*'Key Assumptions'!C14))+(J9*'Key Assumptions'!C15) | K11: =(K6*(('Key Assumptions'!C8/('Key Assumptions'!C8+'Key Assumptions'!C9))*'Key Assumptions'!C13+('Key Assumptions'!C9/('Key Assumptions'!C8+'Key Assumptions'!C9))*'Key Assumptions'!C14))+(K9*'Key Assumptions'!C15) | L11: =(L6*(('Key Assumptions'!C8/('Key Assumptions'!C8+'Key Assumptions'!C9))*'Key Assumptions'!C13+('Key Assumptions'!C9/('Key Assumptions'!C8+'Key Assumptions'!C9))*'Key Assumptions'!C14))+(L9*'Key Assumptions'!C15) | M11: =(M6*(('Key Assumptions'!C8/('Key Assumptions'!C8+'Key Assumptions'!C9))*'Key Assumptions'!C13+('Key Assumptions'!C9/('Key Assumptions'!C8+'Key Assumptions'!C9))*'Key Assumptions'!C14))+(M9*'Key Assumptions'!C15) | N11: =SUM(B11:M11)
A12: Payment processing fees (RM) | B12: =B10*('Key Assumptions'!C32*'Key Assumptions'!C35+'Key Assumptions'!C33*'Key Assumptions'!C36+'Key Assumptions'!C34*'Key Assumptions'!C37) | C12: =C10*('Key Assumptions'!C32*'Key Assumptions'!C35+'Key Assumptions'!C33*'Key Assumptions'!C36+'Key Assumptions'!C34*'Key Assumptions'!C37) | D12: =D10*('Key Assumptions'!C32*'Key Assumptions'!C35+'Key Assumptions'!C33*'Key Assumptions'!C36+'Key Assumptions'!C34*'Key Assumptions'!C37) | E12: =E10*('Key Assumptions'!C32*'Key Assumptions'!C35+'Key Assumptions'!C33*'Key Assumptions'!C36+'Key Assumptions'!C34*'Key Assumptions'!C37) | F12: =F10*('Key Assumptions'!C32*'Key Assumptions'!C35+'Key Assumptions'!C33*'Key Assumptions'!C36+'Key Assumptions'!C34*'Key Assumptions'!C37) | G12: =G10*('Key Assumptions'!C32*'Key Assumptions'!C35+'Key Assumptions'!C33*'Key Assumptions'!C36+'Key Assumptions'!C34*'Key Assumptions'!C37) | H12: =H10*('Key Assumptions'!C32*'Key Assumptions'!C35+'Key Assumptions'!C33*'Key Assumptions'!C36+'Key Assumptions'!C34*'Key Assumptions'!C37) | I12: =I10*('Key Assumptions'!C32*'Key Assumptions'!C35+'Key Assumptions'!C33*'Key Assumptions'!C36+'Key Assumptions'!C34*'Key Assumptions'!C37) | J12: =J10*('Key Assumptions'!C32*'Key Assumptions'!C35+'Key Assumptions'!C33*'Key Assumptions'!C36+'Key Assumptions'!C34*'Key Assumptions'!C37) | K12: =K10*('Key Assumptions'!C32*'Key Assumptions'!C35+'Key Assumptions'!C33*'Key Assumptions'!C36+'Key Assumptions'!C34*'Key Assumptions'!C37) | L12: =L10*('Key Assumptions'!C32*'Key Assumptions'!C35+'Key Assumptions'!C33*'Key Assumptions'!C36+'Key Assumptions'!C34*'Key Assumptions'!C37) | M12: =M10*('Key Assumptions'!C32*'Key Assumptions'!C35+'Key Assumptions'!C33*'Key Assumptions'!C36+'Key Assumptions'!C34*'Key Assumptions'!C37) | N12: =SUM(B12:M12)
A13: Monthly fixed OPEX (RM) | B13: ='OPEX Monthly Opex'!C55 | C13: ='OPEX Monthly Opex'!C55 | D13: ='OPEX Monthly Opex'!C55 | E13: ='OPEX Monthly Opex'!C55 | F13: ='OPEX Monthly Opex'!C55 | G13: ='OPEX Monthly Opex'!C55 | H13: ='OPEX Monthly Opex'!C55 | I13: ='OPEX Monthly Opex'!C55 | J13: ='OPEX Monthly Opex'!C55 | K13: ='OPEX Monthly Opex'!C55 | L13: ='OPEX Monthly Opex'!C55 | M13: ='OPEX Monthly Opex'!C55 | N13: =SUM(B13:M13)
A14: Sales commission (% of gross margin) | B14: =B11*'Key Assumptions'!C43 | C14: =C11*'Key Assumptions'!C43 | D14: =D11*'Key Assumptions'!C43 | E14: =E11*'Key Assumptions'!C43 | F14: =F11*'Key Assumptions'!C43 | G14: =G11*'Key Assumptions'!C43 | H14: =H11*'Key Assumptions'!C43 | I14: =I11*'Key Assumptions'!C43 | J14: =J11*'Key Assumptions'!C43 | K14: =K11*'Key Assumptions'!C43 | L14: =L11*'Key Assumptions'!C43 | M14: =M11*'Key Assumptions'!C43 | N14: =SUM(B14:M14)
A15: Net profit (RM) = Gross margin - fees - OPEX - commission | B15: =B11-B12-B13-B14 | C15: =C11-C12-C13-C14 | D15: =D11-D12-D13-D14 | E15: =E11-E12-E13-E14 | F15: =F11-F12-F13-F14 | G15: =G11-G12-G13-G14 | H15: =H11-H12-H13-H14 | I15: =I11-I12-I13-I14 | ... M15: =M11-M12-M13-M14 | N15: =SUM(B15:M15)
A16: Cumulative net cash flow (RM, starts at 0, excludes CAPEX) | B16: =B15 | C16: =B16+C15 | D16: =C16+D15 | E16: =D16+E15 | F16: =E16+F15 | G16: =F16+G15 | H16: =G16+H15 | I16: =H16+I15 | J16: =I16+J15 | ... M16: =L16+M15
A18: Decision Log #024 validation bar: 3 consecutive months of net profit > 0 and positive cumulative net cash flow
