Workbook

Sheet README
A1: ORIZURU HOLIDAY HOMES LLC — CAPEX & OPEX FINANCIAL MODEL
A2: Dubai, UAE | Trade Licence 1634278 | TRN 105507385000001 | All figures in AED
A4: WHAT IS IN THIS WORKBOOK
A5: Tab | B5: What it does
A6: Funding Summary | B6: START HERE. Total CAPEX, Year-1 OPEX, and the peak cash the business actually needs to fund — tied against the AED 200,000 shareholder capital.
A7: Financial Summary | B7: 5-year P&L, cash flow and returns: EBITDA, net profit, free cash flow, IRR, NPV, MOIC, payback, break-even portfolio size and IRR sensitivities. Year 1 links live to the monthly model; Years 2–5 are driven by the editable inputs in its section 1.
A8: Assumptions | B8: Every OPEX input at Low / Base / High. Set SCENARIO in cell B4 and the whole model re-cuts. Set cell B6 to choose which marketing option is adopted from Month 3.
A9: CAPEX Summary | B9: One-off setup spend rolled up by category.
A10: CAPEX Detail | B10: Every CAPEX line at Low / Base / High: formation & licensing, technology, brand, equipment, deposits.
A11: Unit Setup (1 Unit) | B11: Cost to bring ONE unit live, plus a x1 to x80 portfolio scaling reference.
A12: OPEX Summary | B12: Year-1 OPEX by category, key metrics, and the notes you should read before circulating.
A13: OPEX Monthly | B13: The engine. 12 months across, every cost line down. Edit the yellow unit-ramp row to change the growth path.
A14: Marketing Comparison | B14: Option 1 vs Option 2 head-to-head, break-even units, and what to measure before deciding in Month 3.
A15: AI Subscriptions | B15: AI stack broken out tool by tool. Feeds the AI line in the OPEX model.
A17: THE FOUR LEVERS THAT MOVE EVERYTHING
A18: 1. | B18: Assumptions!B4 — SCENARIO (Low / Base / High).
A19: 2. | B19: Assumptions!B6 — marketing option adopted from Month 3 (or 'Both' to keep running in parallel).
A20: 3. | B20: OPEX Monthly, yellow row — new units signed each month. Currently ramps to 80 units by Month 12, matching the Business Profile's 70–80 Year-1 target. Set every month to 0 except M1 = 1 for a single-unit view.
A21: 4. | B21: Assumptions column F — the active value of any single line. Override any input in its Low/Base/High cells.
A22: 5. | B22: Financial Summary sections 1 and 1b — unit counts for Years 2–5, inflation, headcount, exit multiple, discount rate and the fixed-cost step-up. These drive every return metric.
A24: MODEL BASIS — AS CONFIRMED
A25: • | B25: PURE MANAGEMENT / COMMISSION-ONLY. Orizuru does not master-lease. There is NO unit rent, no unit DEWA and no unit internet anywhere in this model — those sit with the property owner.
A26: • | B26: Unit setup CAPEX is sized for ONE unit. The scaling table on 'Unit Setup (1 Unit)' shows portfolio cost but is not added to the CAPEX total.
A27: • | B27: Directors draw NO salary.
A28: • | B28: Operations & service staff: AED 3,000/month per person, starting with 1 person and scaling with the portfolio via the 'live units per operations staff member' ratio on the Assumptions tab.
A29: • | B29: Both marketing options run in parallel for Months 1–2, then one is adopted.
A30: • | B30: The 2% per signed unit is an ONGOING trailing commission on that unit's monthly revenue, charged every month for as long as the unit is live — not a one-off signing bonus.
A31: • | B31: Figures supplied and used as-is: domain name 3 years AED 387; company stamp AED 137. Both are one-off, so they sit in CAPEX.
A32: • | B32: Shareholder capital is AED 200,000 as confirmed. NOTE: the Business Profile states AED 2,000,000 — the two must be reconciled before the pack goes to the bank. This model uses AED 200,000.
A33: • | B33: Nothing here is sized to the capital figure. Everything is built bottom-up from what the business needs, then compared against the capital available on 'Funding Summary'.
A35: COLOUR LEGEND
A36: Blue text | B36: Hardcoded input — edit freely.
A37: Yellow fill | B37: Key lever, or a figure supplied by management.
A38: Black text | B38: Formula. Do not overwrite.
A39: Green text | B39: Link to another tab in this workbook.
A41: WHAT IS DELIBERATELY EXCLUDED
A42: • | B42: OTA commission (Airbnb / Booking.com, 15–18%). Under a commission-only model this is deducted from gross booking revenue before the owner's split — it is not an Orizuru operating cost. Add it only if your management contracts make Orizuru bear it.
A43: • | B43: Tourism Dirham. Collected from the guest, remitted to DET. Pure pass-through.
A44: • | B44: Corporate Tax itself (9% above AED 375,000 taxable profit) — a tax on profit, not OPEX. The compliance and filing cost IS included.
A45: • | B45: Depreciation on the CAPEX. Non-cash; belongs in the P&L, not an OPEX cash budget.
...

Sheet Funding Summary
A1: FUNDING SUMMARY — WHAT THE BUSINESS ACTUALLY NEEDS
A2: CAPEX and Year-1 OPEX combined. All figures AED. Base case unless the scenario is changed on 'Assumptions'.
A4: 1. CAPITAL EXPENDITURE — one-off
A5: Item | B5: Low | C5: Base | D5: High | E5: Comment
A6: Company setup (formation, tech, brand, equipment, deposits) | B6: ='CAPEX Detail'!G50 -> 60824 | C6: ='CAPEX Detail'!H50 -> 101824 | D6: ='CAPEX Detail'!I50 -> 166324 | E6: Scale-insensitive — the same whether you run 1 unit or 80.
A7: Unit setup — 1 unit | B7: ='Unit Setup (1 Unit)'!D17 -> 6105 | C7: ='Unit Setup (1 Unit)'!E17 -> 9152 | D7: ='Unit Setup (1 Unit)'!F17 -> 13640 | E7: One unit only, as instructed. Multiply on the 'Unit Setup' tab for portfolio scale.
A8: Contingency on company setup | B8: ='CAPEX Detail'!G52 -> 6082.4 | C8: ='CAPEX Detail'!H52 -> 10182.4 | D8: ='CAPEX Detail'!I52 -> 16632.4
A9: TOTAL CAPEX | B9: =SUM(B6:B8) -> 73011.4 | C9: =SUM(C6:C8) -> 121158.4 | D9: =SUM(D6:D8) -> 196596.4
A11: 2. OPERATING EXPENDITURE — Year 1
A12: Total OPEX — Year 1 | C12: ='OPEX Summary'!B14 -> 713738.01 | E12: Active scenario only. Change SCENARIO on 'Assumptions' to see Low / High.
A13: Monthly average OPEX | C13: =C12/12 -> 59478.168 | E13: Year-1 total divided by 12.
A14: Exit run-rate OPEX (Month 12) | C14: ='OPEX Monthly'!N87 -> 113117.82 | E14: The steady-state monthly cost you carry into Year 2.
A16: 3. YEAR-1 TRADING — does it cover itself?
A17: Units signed by Month 12 | C17: ='OPEX Monthly'!N8 -> 80 | E17: Against the Business Profile's 70–80 Year-1 target. Driven by the yellow ramp row on 'OPEX Monthly'.
A18: Gross booking revenue (guest spend across the portfolio) | C18: ='OPEX Monthly'!O11 -> 3755160 | E18: NOT Orizuru's revenue. This is the money flowing through the account — likely what the Business Profile's AED 2.5–4.5M turnover figure refers to.
A19: Orizuru revenue (management fees retained) | C19: ='OPEX Monthly'!O12 -> 751032 | E19: Orizuru's actual top line under the commission-only model. Agree with your accountant which of these two figures goes to the bank — they are very different numbers.
A20: Total OPEX — Year 1 | C20: =C12 -> 713738.01
A21: Operating surplus / (deficit), Year 1 | C21: =C19-C20 -> 37293.985 | E21: Before corporate tax, before depreciation, and before any director remuneration.
A22: OPEX as % of Orizuru revenue | C22: =IF(C19=0,0,C20/C19) -> 0.95034301 | E22: Above 100% means Year 1 runs at an operating loss — normal while a portfolio ramps from zero.
A24: 4. TOTAL FUNDING REQUIREMENT
A25: Peak cumulative operating cash deficit | C25: =MIN(0,MIN('OPEX Monthly'!C93:N93)) -> -76726.005 | E25: The worst the cumulative operating cash position ever gets during Year 1. THIS is the working capital to fund — not the annual OPEX figure.
A26: Total CAPEX | C26: =C9 -> 121158.4
A27: Safety buffer | B27: 0.2 | C27: =(ABS(C25)+C26)*B27 -> 39576.881 | E27: Cover for the ramp landing slower than planned. Edit the percentage in column B.
A28: TOTAL FUNDING REQUIRED | C28: =ABS(C25)+C26+C27 -> 237461.29
A29: Shareholder capital available | C29: 200000 | E29: AED 200,000 as confirmed. The Business Profile states AED 2,000,000 — reconcile before submission.
A30: Headroom / (shortfall) | C30: =C29-C28 -> -37461.286 | E30: Negative means the ramp above cannot be funded from AED 200,000. Fix it by slowing the unit ramp, taking the Low CAPEX case, or re-charging unit-level OPEX to owners — see note 6 below.
A32: 5. READ THIS BEFORE YOU CIRCULATE
A33: • STAFFING SCALES WITH THE PORTFOLIO. Headcount is no longer fixed at one person: it is driven by the 'live units per operations staff member' ratio on the Assumptions tab (35 in the Base case, floor of one person), so the team grows through Year 1 as units come live. Salary stays at the AED 3,000/month specified. That rate is low for Dubai even for an operations assistant — if hiring proves harder than expected, raise the salary input rather than cutting the ratio.
A34: • THE 2% IS MODELLED AS ONGOING. It applies to every live unit every month, indefinitely, as confirmed. By Month 12 it is one of the largest single lines in the model and it never stops growing with the portfolio. If a one-off signing bonus was intended, this needs re-cutting — over three years the difference is very large.
A35: • REVENUE RECOGNITION. The Business Profile projects AED 2.5–4.5M Year-1 turnover. Under pure commission-only, Orizuru's own revenue at 70–80 units is materially lower; the AED 2.5–4.5M is closer to gross booking value passing through the account. Settle which figure you are presenting before the KYC pack goes to the bank.
A36: • CAPEX IS SIZED FOR ONE UNIT, OPEX RAMPS TO 80. This is deliberate and as instructed, but the two tabs are not on the same basis. If you take the portfolio to 80 units, the unit-setup CAPEX scales with it — see the scaling table on 'Unit Setup (1 Unit)' and add it to the funding requirement above.
A37: • MOST UNIT-LEVEL OPEX IS RE-CHARGEABLE. Housekeeping, DET permit renewals and consumables are commonly billed to the owner or the guest. Set those assumptions to 0 if your management contracts pass them through — it changes the OPEX total substantially.
A38: • AT AED 200,000 THE BASE CASE DOES NOT FUND ITSELF. Base CAPEX (121,158) plus the peak operating cash deficit (76,726) plus a 20% buffer comes to 237,461 against 200,000 available — a shortfall of about 37,000. Two levers close it: (a) take the Low CAPEX case, deferring the full website build and brand spend until cash turns positive, which alone gets you to roughly 20,000 of headroom; (b) re-charge unit-level OPEX (housekeeping, DET permit renewals, consumables) to owners and guests, which is standard Dubai practice. Doing both leaves about 38,000 of headroom and is the recommended path.
A39: • DO NOT TRY TO FIX IT BY SLOWING THE RAMP. This is counter-intuitive but the model is unambiguous: cutting the ramp from 80 units to 46 by Month 12 makes the peak cash deficit WORSE, not better (119,632 vs 76,726). Fixed OPEX — office, licence, staff, technology — runs regardless, so a slower ramp simply means paying it for longer before revenue catches up. If capital is tight, cut CAPEX and re-charge OPEX; do not cut growth.

Sheet Financial Summary
A1: FINANCIAL SUMMARY — 5-YEAR P&L, CASH FLOW & RETURNS
A2: All figures AED. Year 1 links live to the monthly model; Years 2–5 are driven by the inputs in section 1.
A4: 1. DRIVERS — edit the blue cells to re-cut every number below
A5: Line item | B5: Year 1 | C5: Year 2 | D5: Year 3 | E5: Year 4 | F5: Year 5 | G5: Basis / note
A6: Units under management at year end | B6: ='OPEX Monthly'!N8 -> 80 | C6: 130 | D6: 180 | E6: 220 | F6: 250 | G6: Year 1 links to the monthly model. Years 2–5 are your growth plan — the single biggest lever here.
A7: Average live units during the year | B7: =AVERAGE('OPEX Monthly'!C9:N9) -> 30.5 | C7: =(B6+C6)/2 -> 105 | D7: =(C6+D6)/2 -> 155 | E7: =(D6+E6)/2 -> 200 | F7: =(E6+F6)/2 -> 235 | G7: Revenue is earned by units that are LIVE, not units signed. Year 1 averages the actual monthly ramp.
A8: Live unit-months in the year | B8: =SUM('OPEX Monthly'!C9:N9) -> 366 | C8: =C7*12 -> 1260 | D8: =D7*12 -> 1860 | E8: =E7*12 -> 2400 | F8: =F7*12 -> 2820 | G8: Drives every per-unit variable cost.
A9: Price inflation (ADR) | B9: =0 -> 0 | C9: 0.03 | D9: 0.03 | E9: 0.03 | F9: 0.03 | G9: Applied to ADR from Year 2. Dubai STR rates have run ahead of this; 3% is deliberately conservative.
A10: Cost inflation | B10: =0 -> 0 | C10: 0.04 | D10: 0.04 | E10: 0.04 | F10: 0.04 | G10: Applied to all fixed and per-unit costs from Year 2.
A11: Average Daily Rate | B11: =Assumptions!$F$11 -> 450 | C11: =B11*(1+C9) -> 463.5 | D11: =C11*(1+D9) -> 477.405 | E11: =D11*(1+E9) -> 491.72715 | F11: =E11*(1+F9) -> 506.47896 | G11: Year 1 from the Assumptions tab.
A12: Gross booking revenue per unit per month | B12: =B11*Assumptions!$F$12*Assumptions!$F$13 -> 10260 | C12: =C11*Assumptions!$F$12*Assumptions!$F$13 -> 10567.8 | D12: =D11*Assumptions!$F$12*Assumptions!$F$13 -> 10884.834 | E12: =E11*Assumptions!$F$12*Assumptions!$F$13 -> 11211.379 | F12: =F11*Assumptions!$F$12*Assumptions!$F$13 -> 11547.72 | G12: What the guest pays. NOT Orizuru revenue.
A13: Operations & service headcount (average) | B13: =AVERAGE('OPEX Monthly'!C10:N10) -> 1.5 | C13: =MAX(Assumptions!$F$19,ROUNDUP(C7/Assumptions!$F$20,0)) -> 3 | D13: =MAX(Assumptions!$F$19,ROUNDUP(D7/Assumptions!$F$20,0)) -> 5 | E13: =MAX(Assumptions!$F$19,ROUNDUP(E7/Assumptions!$F$20,0)) -> 6 | F13: =MAX(Assumptions!$F$19,ROUNDUP(F7/Assumptions!$F$20,0)) -> 7 | G13: Driven by the 'live units per operations staff member' ratio on the Assumptions tab, with a floor of one person. Year 1 is the average of the actual monthly ramp. Change the ratio there and headcount, staff cost and EBITDA all move together.
A14: Average salary per operations head (monthly) | B14: =Assumptions!$F$21 -> 3000 | C14: =B14*(1+C10) -> 3120 | D14: =C14*(1+D10) -> 3244.8 | E14: =D14*(1+E10) -> 3374.592 | F14: =E14*(1+F10) -> 3509.5757 | G14: Year 1 as specified by management.
A15: 1b. FINANCIAL INPUTS — used by the cash flow and returns sections below
A16: Input | B16: Value | G16: Basis / note
A17: Fixed-cost step-up with portfolio growth | B17: 0.4 | G17: Share of portfolio growth that flows into 'other fixed costs'. A business running 235 units does not carry the same office, marketing and admin base as one running 30. At 40%, a doubling of the portfolio raises fixed costs by 40%. Set to 0% to assume pure operating leverage — optimistic, and the reason unadjusted models show implausible margins.
A18: Share of unit-onboarding cost borne by Orizuru | B18: 0 | G18: SET TO 0% per the instruction that only ONE unit's setup sits in CAPEX — i.e. onboarding is re-charged to the owner. Raise it to see what self-funding the rollout costs. Sensitivity below.
A19: Working capital as % of revenue | B19: 0.05 | G19: Cash tied up in guest and OTA settlement timing.
A20: Discount rate (cost of equity) | B20: 0.2 | G20: 20% is a reasonable hurdle for an unlisted, pre-trading UAE SME. Lower it and NPV rises.
A21: Exit EBITDA multiple | B21: 4 | G21: Assumes a trade sale at the end of Year 5. 4x final-year EBITDA is typical for an asset-light property-management book of this size.
A22: Shareholder capital invested (Year 0) | B22: ='Funding Summary'!C29 -> 200000 | G22: Links to the Funding Summary.
A23: 2. INCOME STATEMENT (P&L)
A24: Line item | B24: Year 1 | C24: Year 2 | D24: Year 3 | E24: Year 4 | F24: Year 5 | G24: Basis / note
A25: Gross booking value handled (memo) | B25: ='OPEX Monthly'!O11 -> 3755160 | C25: =C7*C12*12 -> 13315428 | D25: =D7*D12*12 -> 20245791 | E25: =E7*E12*12 -> 26907310 | F25: =F7*F12*12 -> 32564572 | G25: MEMO ONLY — this is guest money flowing through the account, not revenue. Never present this as turnover.
A26: REVENUE — management fees retained | B26: ='OPEX Monthly'!O12 -> 751032 | C26: =C25*Assumptions!$F$15 -> 2663085.6 | D26: =D25*Assumptions!$F$15 -> 4049158.2 | E26: =E25*Assumptions!$F$15 -> 5381461.9 | F26: =F25*Assumptions!$F$15 -> 6512914.3 | G26: Orizuru's actual top line under the commission-only model.
A27: Variable costs
A28: Unit operations (permits, cleaning, consumables, maintenance, linen) | B28: ='OPEX Monthly'!O61 -> 196420 | C28: =C8*(Assumptions!$F$52/12+Assumptions!$F$53+Assumptions!$F$54+Assumptions!$F$55+Assumptions!$F$56)*(1+C10)^(1) -> 703248 | D28: =D8*(Assumptions!$F$52/12+Assumptions!$F$53+Assumptions!$F$54+Assumptions!$F$55+Assumptions!$F$56)*(1+D10)^(2) -> 1079653.1 | E28: =E8*(Assumptions!$F$52/12+Assumptions!$F$53+Assumptions!$F$54+Assumptions!$F$55+Assumptions!$F$56)*(1+E10)^(3) -> 1448824.8 | F28: =F8*(Assumptions!$F$52/12+Assumptions!$F$53+Assumptions!$F$54+Assumptions!$F$55+Assumptions!$F$56)*(1+F10)^(4) -> 1770463.9 | G28: Scales directly with the portfolio. Much of it is re-chargeable to owners — see the note at the foot of this tab.
A29: Unit technology (PMS, dynamic pricing, smart locks) | B29: ='OPEX Monthly'!C9*0+SUM('OPEX Monthly'!C9:N9)*(Assumptions!$F$43+Assumptions!$F$44+Assumptions!$F$45) -> 45750 | C29: =C8*(Assumptions!$F$43+Assumptions!$F$44+Assumptions!$F$45)*(1+C10)^(1) -> 163800 | D29: =D8*(Assumptions!$F$43+Assumptions!$F$44+Assumptions!$F$45)*(1+D10)^(2) -> 251472 | E29: =E8*(Assumptions!$F$43+Assumptions!$F$44+Assumptions!$F$45)*(1+E10)^(3) -> 337459.2 | F29: =F8*(Assumptions!$F$43+Assumptions!$F$44+Assumptions!$F$45)*(1+F10)^(4) -> 412375.14 | G29: Priced per property, so it scales one-for-one with units.
A30: Unit-acquisition commission (2%, ongoing) | B30: ='OPEX Monthly'!O42 -> 75103.2 | C30: =C25*Assumptions!$F$40 -> 266308.56 | D30: =D25*Assumptions!$F$40 -> 404915.82 | E30: =E25*Assumptions!$F$40 -> 538146.19 | F30: =F25*Assumptions!$F$40 -> 651291.43 | G30: Charged on every live unit every month, indefinitely. Grows in line with the portfolio and never stops.
A31: Total variable costs | B31: =B28+B29+B30 -> 317273.2 | C31: =C28+C29+C30 -> 1133356.6 | D31: =D28+D29+D30 -> 1736040.9 | E31: =E28+E29+E30 -> 2324430.2 | F31: =F28+F29+F30 -> 2834130.5
A32: GROSS PROFIT | B32: =B26-B31 -> 433758.8 | C32: =C26-C31 -> 1529729 | D32: =D26-D31 -> 2313117.3 | E32: =E26-E31 -> 3057031.7 | F32: =F26-F31 -> 3678783.8
A33: Gross margin | B33: =IF(B26=0,0,B32/B26) -> 0.57755036 | C33: =IF(C26=0,0,C32/C26) -> 0.57441978 | D33: =IF(D26=0,0,D32/D26) -> 0.57125881 | E33: =IF(E26=0,0,E32/E26) -> 0.56806714 | F33: =IF(F26=0,0,F32/F26) -> 0.56484449 | G33: Contribution left over after the costs that grow with the portfolio.
A34: Fixed operating costs
A35: Staff (salaries, visas, insurance, gratuity, WPS) | B35: ='OPEX Monthly'!O22 -> 64242 | C35: =C13*C14*12*($B$35/MAX(1,$B$13*$B$14*12)) -> 133623.36 | D35: =D13*D14*12*($B$35/MAX(1,$B$13*$B$14*12)) -> 231613.82 | E35: =E13*E14*12*($B$35/MAX(1,$B$13*$B$14*12)) -> 289054.05 | F35: =F13*F14*12*($B$35/MAX(1,$B$13*$B$14*12)) -> 350718.92 | G35: Headcount x salary x 12, grossed up by the same employment loading as Year 1 (visas, mandatory insurance, gratuity, WPS) — roughly 19% on top of salary. Directors remain unpaid throughout.
A36: All other fixed costs (marketing, technology, office, compliance, contingency) | B36: ='OPEX Summary'!B14-B28-B29-B30-B35 -> 332222.81 | C36: =B36*(1+C10)*(1+$B$17*IF(B7=0,0,C7/B7-1)) -> 683093.68 | D36: =C36*(1+D10)*(1+$B$17*IF(C7=0,0,D7/C7-1)) -> 845735.03 | E36: =D36*(1+E10)*(1+$B$17*IF(D7=0,0,E7/D7-1)) -> 981707.4 | F36: =E36*(1+F10)*(1+$B$17*IF(E7=0,0,F7/E7-1)) -> 1092444 | G36: Year 1 is derived so that this tab ties EXACTLY to total Year-1 OPEX on the monthly model. Years 2–5 grow with cost inflation PLUS a step-up for portfolio growth (driver in section 1b) — a bigger book needs a bigger office, more marketing and more admin.
A37: Total fixed costs | B37: =B35+B36 -> 396464.81 | C37: =C35+C36 -> 816717.04 | D37: =D35+D36 -> 1077348.9 | E37: =E35+E36 -> 1270761.4 | F37: =F35+F36 -> 1443162.9
A38: EBITDA | B38: =B32-B37 -> 37293.985 | C38: =C32-C37 -> 713012 | D38: =D32-D37 -> 1235768.5 | E38: =E32-E37 -> 1786270.3 | F38: =F32-F37 -> 2235620.9 | G38: Earnings before interest, tax, depreciation and amortisation. The headline operating profit measure.
A39: EBITDA margin | B39: =IF(B26=0,0,B38/B26) -> 0.049656986 | C39: =IF(C26=0,0,C38/C26) -> 0.26773905 | D39: =IF(D26=0,0,D38/D26) -> 0.30519144 | E39: =IF(E26=0,0,E38/E26) -> 0.3319303 | F39: =IF(F26=0,0,F38/F26) -> 0.34325968 | G39: Asset-light property management typically runs 20–35% at scale.
A40: Capital expenditure in year | B40: ='Funding Summary'!C9 -> 121158.4 | C40: =(C6-B6)*'Unit Setup (1 Unit)'!E17*$B$18 -> 0 | D40: =(D6-C6)*'Unit Setup (1 Unit)'!E17*$B$18 -> 0 | E40: =(E6-D6)*'Unit Setup (1 Unit)'!E17*$B$18 -> 0 | F40: =(F6-E6)*'Unit Setup (1 Unit)'!E17*$B$18 -> 0 | G40: Year 1 is the full CAPEX from the Funding Summary. Years 2–5 are unit-onboarding cost on NEW units only, scaled by the share Orizuru bears (driver in section 4).
A41: Depreciation & amortisation | B41: =B40/3 -> 40386.133 | C41: =SUM($B40:C40)/3 -> 40386.133 | D41: =SUM($B40:D40)/3 -> 40386.133 | E41: =SUM(C40:E40)/3 -> 0 | F41: =SUM(D40:F40)/3 -> 0 | G41: Straight line over 3 years. Non-cash — added back in the cash flow below.
...

Sheet Assumptions
A1: OPEX ASSUMPTIONS — ORIZURU HOLIDAY HOMES LLC
A2: All figures AED unless stated. Blue = editable input. Yellow = figure supplied by management or a key lever.
A4: SCENARIO | B4: Base | C4: Change this cell to Low / Base / High. Every 'Active' figure below and the whole monthly model follow it. | J4: Low
A5: Scenario index | B5: =MATCH($B$4,$J$4:$J$6,0) -> 2 | J5: Base
A6: Option adopted from Month 3 | B6: Option 2 | C6: Both options run in Months 1–2 per management. From Month 3 the model keeps whichever you select here. Select 'Both' to keep running them in parallel all year. | J6: High
A7: Parallel-run months | B7: 2 | C7: Per management: run both marketing options together for the first 2 months to see which works.
A9: Assumption | B9: Unit | C9: Low | D9: Base | E9: High | F9: Active | G9: Source / note
A10: 1. REVENUE DRIVERS — needed to size the 2% commission, gateway fees and cost-to-revenue ratios
A11: Average Daily Rate (ADR) per unit | B11: AED/night | C11: 380 | D11: 450 | E11: 550 | F11: =INDEX(C11:E11,1,Assumptions!$B$5) -> 450 | G11: Premium 1BR short-term rental, Dubai. Drives the revenue base for the 2% marketing commission.
A12: Occupancy rate | B12: % | C12: 0.65 | D12: 0.75 | E12: 0.82 | F12: =INDEX(C12:E12,1,Assumptions!$B$5) -> 0.75 | G12: Dubai holiday-home market runs high; 75% is a realistic stabilised assumption.
A13: Nights per month | B13: nights | C13: 30.4 | D13: 30.4 | E13: 30.4 | F13: =INDEX(C13:E13,1,Assumptions!$B$5) -> 30.4 | G13: 365 / 12.
A14: Gross booking revenue per unit per month | B14: AED | C14: =C11*C12*C13 -> 7508.8 | D14: =D11*D12*D13 -> 10260 | E14: =E11*E12*E13 -> 13710.4 | F14: =INDEX(C14:E14,1,Assumptions!$B$5) -> 10260 | G14: Calculated. This is the GUEST's spend on that unit — not Orizuru's revenue.
A15: Management fee retained by Orizuru | B15: % of gross | C15: 0.15 | D15: 0.2 | E15: 0.25 | F15: =INDEX(C15:E15,1,Assumptions!$B$5) -> 0.2 | G15: Dubai holiday-home management contracts run 15–25%. This IS Orizuru's revenue under the commission-only model.
A16: Orizuru revenue per unit per month | B16: AED | C16: =C14*C15 -> 1126.32 | D16: =D14*D15 -> 2052 | E16: =E14*E15 -> 3427.6 | F16: =INDEX(C16:E16,1,Assumptions!$B$5) -> 2052 | G16: Calculated. Compare against the Business Profile's AED 2.5–4.5M turnover target — see the reconciliation note on the README tab.
A17: 2. STAFF — Dubai payroll
A18: Directors' salary | B18: AED/month | C18: 0 | D18: 0 | E18: 0 | F18: =INDEX(C18:E18,1,Assumptions!$B$5) -> 0 | G18: Per management: directors will NOT draw a salary. Note for the bank — this understates the true cost of running the business, since two directors are working unpaid.
A19: Operations & service staff — minimum headcount | B19: persons | C19: 1 | D19: 1 | E19: 1 | F19: =INDEX(C19:E19,1,Assumptions!$B$5) -> 1 | G19: Per management: the business starts with 1 person. Actual headcount rises with the portfolio — see the ratio below.
A20: Live units per operations staff member | B20: units/person | C20: 45 | D20: 35 | E20: 25 | F20: =INDEX(C20:E20,1,Assumptions!$B$5) -> 35 | G20: The staffing ratio. One person cannot run 80 units alone: check-ins, guest support, housekeeping coordination, maintenance and owner reporting across a portfolio spread over Dubai. 35 units per person is realistic with housekeeping outsourced. A LOWER number means MORE staff and higher cost — which is why the High-cost scenario uses 25.
A21: Operations & service staff — salary | B21: AED/month | C21: 3000 | D21: 3000 | E21: 3000 | F21: =INDEX(C21:E21,1,Assumptions!$B$5) -> 3000 | G21: Per management: AED 3,000/month.
A22: Staff visa, medical insurance & EID — monthly accrual per UAE employee | B22: AED/month | C22: 250 | D22: 380 | E22: 550 | F22: =INDEX(C22:E22,1,Assumptions!$B$5) -> 380 | G22: 2-year residence visa and mandatory Dubai health insurance spread monthly. Real cash cost even though it is billed in lumps.
A23: End-of-service gratuity accrual | B23: % of salary | C23: 0.058 | D23: 0.058 | E23: 0.058 | F23: =INDEX(C23:E23,1,Assumptions!$B$5) -> 0.058 | G23: UAE Labour Law: 21 days' basic pay per year of service for the first 5 years = 5.8% of salary. Legally payable — accrue it or it becomes a nasty surprise.
A24: WPS / payroll processing fee | B24: AED/employee/mo | C24: 8 | D24: 15 | E24: 25 | F24: =INDEX(C24:E24,1,Assumptions!$B$5) -> 15 | G24: Wage Protection System is mandatory for MOHRE-sponsored staff.
A25: 3. MARKETING OPTION 1 — FULLY ONLINE (4 hrs/day)
A26: Team size | B26: persons | C26: 2 | D26: 3 | E26: 4 | F26: =INDEX(C26:E26,1,Assumptions!$B$5) -> 3 | G26: Per management: 2–4 persons.
A27: Cost per person | B27: AED/month | C27: 500 | D27: 600 | E27: 700 | F27: =INDEX(C27:E27,1,Assumptions!$B$5) -> 600 | G27: Per management: AED 500–700 per person.
A28: Digital ads & owner lead generation | B28: AED/month | C28: 800 | D28: 1500 | E28: 2800 | F28: =INDEX(C28:E28,1,Assumptions!$B$5) -> 1500 | G28: A fully-online team without a paid lead flow will stall. This is the cost of feeding them owner leads.
A29: Outreach tooling, CRM & lead database | B29: AED/month | C29: 150 | D29: 280 | E29: 450 | F29: =INDEX(C29:E29,1,Assumptions!$B$5) -> 280 | G29: LinkedIn Sales Navigator / Property Finder lead access / CRM seats.
A30: Team coordination & QA time | B30: AED/month | C30: 0 | D30: 300 | E30: 600 | F30: =INDEX(C30:E30,1,Assumptions!$B$5) -> 300 | G30: Someone has to check the work. At 2–4 remote people this is light but not zero.
A31: 4. MARKETING OPTION 2 — REMOTE OFFICE OUTSIDE UAE (4 hrs/day)
A32: Team size | B32: persons | C32: 4 | D32: 5 | E32: 6 | F32: =INDEX(C32:E32,1,Assumptions!$B$5) -> 5 | G32: Per management: 4–6 persons.
A33: Cost per person | B33: AED/month | C33: 180 | D33: 240 | E33: 300 | F33: =INDEX(C33:E33,1,Assumptions!$B$5) -> 240 | G33: Per management: AED 180–300 per person.
A34: Coworking area rent | B34: AED/month | C34: 1350 | D34: 1425 | E34: 1500 | F34: =INDEX(C34:E34,1,Assumptions!$B$5) -> 1425 | G34: Per management: AED 1,350–1,500.
A35: Local internet, utilities & equipment | B35: AED/month | C35: 200 | D35: 350 | E35: 550 | F35: =INDEX(C35:E35,1,Assumptions!$B$5) -> 350 | G35: Not in the original brief but unavoidable — a physical room needs connectivity and machines.
A36: On-site supervisor / team lead | B36: AED/month | C36: 0 | D36: 500 | E36: 900 | F36: =INDEX(C36:E36,1,Assumptions!$B$5) -> 500 | G36: Not in the original brief. 4–6 people in a physical room with no supervisor will drift. Recommend keeping this.
A37: Digital ads & lead generation | B37: AED/month | C37: 400 | D37: 900 | E37: 1600 | F37: =INDEX(C37:E37,1,Assumptions!$B$5) -> 900 | G37: Lower than Option 1 — a larger team does more manual prospecting, so less paid volume is needed.
A38: Local compliance / entity or contractor arrangement | B38: AED/month | C38: 0 | D38: 400 | E38: 900 | F38: =INDEX(C38:E38,1,Assumptions!$B$5) -> 400 | G38: Not in the original brief. Engaging staff outside the UAE needs a compliant contracting route. Flagging it rather than pretending it is free.
A39: 5. UNIT-ACQUISITION COMMISSION — the 2% per management
A40: Trailing commission on each signed unit | B40: % | C40: 0.02 | D40: 0.02 | E40: 0.02 | F40: =INDEX(C40:E40,1,Assumptions!$B$5) -> 0.02 | G40: Per management: 2% for each unit signed, ONGOING on that unit's monthly revenue.
A41: Commission base | B41: — | C41: 1 | D41: 1 | E41: 1 | F41: =INDEX(C41:E41,1,Assumptions!$B$5) -> 1 | G41: 1 = 2% of the unit's GROSS booking revenue (i.e. c.10% of Orizuru's management fee on that unit). 2 = 2% of Orizuru's management fee only (far cheaper, far weaker incentive). Change the number to switch base.
A42: 6. TECHNOLOGY, PLATFORM & AI
...

Sheet CAPEX Summary
A1: CAPEX SUMMARY BY CATEGORY
A2: All figures AED. Base case is the presentation figure; Low / High frame the range.
A4: Category | B4: Low | C4: Base | D4: High | E4: % of Base total | F4: Comment
A5: A. COMPANY FORMATION, LICENSING & REGULATORY | B5: ='CAPEX Detail'!G45 -> 29437 | C5: ='CAPEX Detail'!H45 -> 45337 | D5: ='CAPEX Detail'!I45 -> 62837 | E5: =IF($C$12=0,0,C5/$C$12) -> 0.37419609 | F5: Largely fixed and largely unavoidable. Most of it is already incurred as at 03/07/2026.
A6: B. TECHNOLOGY, PLATFORM & DIGITAL SETUP | B6: ='CAPEX Detail'!G46 -> 10287 | C6: ='CAPEX Detail'!H46 -> 19787 | D6: ='CAPEX Detail'!I46 -> 37887 | E6: =IF($C$12=0,0,C6/$C$12) -> 0.16331513 | F6: The direct booking engine is the highest-return line in the whole CAPEX — it removes OTA commission on repeat guests.
A7: C. BRAND & MARKETING SETUP | B7: ='CAPEX Detail'!G47 -> 6200 | C7: ='CAPEX Detail'!H47 -> 11900 | D7: ='CAPEX Detail'!I47 -> 23800 | E7: =IF($C$12=0,0,C7/$C$12) -> 0.09821853 | F7: Directly enables both marketing options. The owner pitch deck is what the acquisition team actually sells with.
A8: D. OFFICE EQUIPMENT & FURNITURE (DUBAI) | B8: ='CAPEX Detail'!G48 -> 9900 | C8: ='CAPEX Detail'!H48 -> 15000 | D8: ='CAPEX Detail'!I48 -> 24300 | E8: =IF($C$12=0,0,C8/$C$12) -> 0.12380487 | F8: Scale-insensitive. Same cost at 1 unit or 80.
A9: E. DEPOSITS & PREPAYMENTS | B9: ='CAPEX Detail'!G49 -> 5000 | C9: ='CAPEX Detail'!H49 -> 9800 | D9: ='CAPEX Detail'!I49 -> 17500 | E9: =IF($C$12=0,0,C9/$C$12) -> 0.080885849 | F9: Mostly refundable. Cash timing rather than true cost.
A10: Unit setup — 1 unit | B10: ='CAPEX Detail'!G51 -> 6105 | C10: ='CAPEX Detail'!H51 -> 9152 | D10: ='CAPEX Detail'!I51 -> 13640 | E10: =IF($C$12=0,0,C10/$C$12) -> 0.075537478 | F10: Per management: one unit only. Multiply on the 'Unit Setup' tab for portfolio scale.
A11: Contingency | B11: ='CAPEX Detail'!G52 -> 6082.4 | C11: ='CAPEX Detail'!H52 -> 10182.4 | D11: ='CAPEX Detail'!I52 -> 16632.4 | E11: =IF($C$12=0,0,C11/$C$12) -> 0.084042047 | F11: 10% of company-setup subtotal.
A12: TOTAL CAPEX | B12: =SUM(B5:B11) -> 73011.4 | C12: =SUM(C5:C11) -> 121158.4 | D12: =SUM(D5:D11) -> 196596.4 | E12: =IF($C$12=0,0,SUM(E5:E11)) -> 1
A15: READ-ACROSS
A16: • Shareholder capital is AED 200,000 as confirmed. The Business Profile states AED 2,000,000 — reconcile the two before submission. This CAPEX is not sized to either figure; it is built bottom-up from what the business needs. At AED 200,000, CAPEX alone consumes a significant share of the capital — see 'Funding Summary'.
A17: • Because Orizuru operates commission-only, CAPEX is genuinely light: there is no furniture, no unit deposits and no master-lease prepayment. The heavy spend in this business is OPEX, not CAPEX.
A18: • The single largest scaling risk is NOT in this workbook: it is the per-unit setup cost multiplied out. At the Business Profile's 70–80 unit target the unit-setup line alone becomes material — see the scaling table on the 'Unit Setup' tab.
A19: • Refundable items (office deposit, DEWA deposit, labour guarantee) are inside the total. Strip them out if presenting a 'true sunk cost' figure.

Sheet CAPEX Detail
A1: CAPEX DETAIL — ONE-OFF SETUP EXPENDITURE
A2: Company formation, licensing, technology, brand and equipment. Unit setup is on the 'Unit Setup (1 Unit)' tab.
A4: Ref | B4: Line item | C4: Qty | D4: Unit cost — Low | E4: Unit cost — Base | F4: Unit cost — High | G4: Total — Low | H4: Total — Base | I4: Total — High | J4: Timing / status | K4: Basis / note
A5: A. COMPANY FORMATION, LICENSING & REGULATORY
A6: A1 | B6: DED trade licence — initial issue (Vacation Homes Rental) | C6: 1 | D6: 13500 | E6: 17500 | F6: 22000 | G6: =$C6*D6 -> 13500 | H6: =$C6*E6 -> 17500 | I6: =$C6*F6 -> 22000 | J6: Incurred — 03/07/2026 | K6: Mainland LLC commercial licence. Licence No. 1634278 per the Business Profile.
A7: A2 | B7: Trade name reservation & initial approval | C7: 1 | D7: 900 | E7: 1200 | F7: 1600 | G7: =$C7*D7 -> 900 | H7: =$C7*E7 -> 1200 | I7: =$C7*F7 -> 1600 | J7: Incurred — 03/07/2026 | K7: DED fixed fees.
A8: A3 | B8: MOA drafting & notarisation | C8: 1 | D8: 1800 | E8: 2500 | F8: 3500 | G8: =$C8*D8 -> 1800 | H8: =$C8*E8 -> 2500 | I8: =$C8*F8 -> 3500 | J8: Incurred — 03/07/2026 | K8: Three-shareholder structure per the Business Profile (Podocarpus 70% / Atayev 16% / Mamiyev 14%).
A9: A4 | B9: Ejari / tenancy registration for the licensed address | C9: 1 | D9: 1500 | E9: 2200 | F9: 3200 | G9: =$C9*D9 -> 1500 | H9: =$C9*E9 -> 2200 | I9: =$C9*F9 -> 3200 | J9: Incurred — 03/07/2026 | K9: Fronds Building – Office 02, Goze Industrial Third. Required to hold the licence.
A10: A5 | B10: Immigration establishment card | C10: 1 | D10: 1000 | E10: 1500 | F10: 2200 | G10: =$C10*D10 -> 1000 | H10: =$C10*E10 -> 1500 | I10: =$C10*F10 -> 2200 | J10: Month 1 | K10: Required before any employment visa can be issued.
A11: A6 | B11: MOHRE labour file / e-Channel registration | C11: 1 | D11: 1600 | E11: 2300 | F11: 3200 | G11: =$C11*D11 -> 1600 | H11: =$C11*E11 -> 2300 | I11: =$C11*F11 -> 3200 | J11: Month 1 | K11: Needed to sponsor the operations & service staff member.
A12: A7 | B12: DET (ex-DTCM) holiday-home OPERATOR permit — company level | C12: 1 | D12: 4500 | E12: 7500 | F12: 12000 | G12: =$C12*D12 -> 4500 | H12: =$C12*E12 -> 7500 | I12: =$C12*F12 -> 12000 | J12: Month 1 | K12: Distinct from the per-unit permit. Without it the company cannot legally list short-term rentals.
A13: A8 | B13: Corporate bank account opening & KYC pack | C13: 1 | D13: 0 | E13: 500 | F13: 1500 | G13: =$C13*D13 -> 0 | H13: =$C13*E13 -> 500 | I13: =$C13*F13 -> 1500 | J13: Month 1 | K13: Corporate current account, multi-currency AED/USD/EUR per the Business Profile.
A14: A9 | B14: VAT registration & Corporate Tax registration | C14: 1 | D14: 0 | E14: 1000 | F14: 2500 | G14: =$C14*D14 -> 0 | H14: =$C14*E14 -> 1000 | I14: =$C14*F14 -> 2500 | J14: Incurred | K14: TRN 105507385000001 already issued per the Business Profile. Cost shown for completeness.
A15: A10 | B15: Company stamp | C15: 1 | D15: 137 | E15: 137 | F15: 137 | G15: =$C15*D15 -> 137 | H15: =$C15*E15 -> 137 | I15: =$C15*F15 -> 137 | J15: Incurred | K15: Actual figure supplied by management — AED 137.
A16: A11 | B16: Employment visa — operations & service staff (1 person) | C16: 1 | D16: 4500 | E16: 6000 | F16: 8000 | G16: =$C16*D16 -> 4500 | H16: =$C16*E16 -> 6000 | I16: =$C16*F16 -> 8000 | J16: Month 1 | K16: Entry permit, status change, medical, Emirates ID, 2-year residence visa.
A17: A12 | B17: Refundable labour guarantee / bank guarantee (1 employee) | C17: 1 | D17: 0 | E17: 3000 | F17: 3000 | G17: =$C17*D17 -> 0 | H17: =$C17*E17 -> 3000 | I17: =$C17*F17 -> 3000 | J17: Month 1 | K17: MOHRE requirement. Refundable, but cash out on day one.
A18: B. TECHNOLOGY, PLATFORM & DIGITAL SETUP
A19: B1 | B19: Domain name registration — 3 years | C19: 1 | D19: 387 | E19: 387 | F19: 387 | G19: =$C19*D19 -> 387 | H19: =$C19*E19 -> 387 | I19: =$C19*F19 -> 387 | J19: Incurred | K19: Actual figure supplied by management — AED 387 for 3 years.
A20: B2 | B20: Website build + direct booking engine | C20: 1 | D20: 7000 | E20: 12000 | F20: 22000 | G20: =$C20*D20 -> 7000 | H20: =$C20*E20 -> 12000 | I20: =$C20*F20 -> 22000 | J20: Month 1–2 | K20: The Business Profile commits to a direct booking portal. Direct bookings avoid the 15–18% OTA commission, so this pays back fastest of any line here.
A21: B3 | B21: PMS / channel manager onboarding & setup fee (Hostaway, Guesty or equivalent) | C21: 1 | D21: 1800 | E21: 3000 | F21: 5500 | G21: =$C21*D21 -> 1800 | H21: =$C21*E21 -> 3000 | I21: =$C21*F21 -> 5500 | J21: Month 1 | K21: One-off implementation. The recurring per-unit licence sits in OPEX.
A22: B4 | B22: Channel account setup & verification (Airbnb, Booking.com, direct) | C22: 1 | D22: 0 | E22: 800 | F22: 1800 | G22: =$C22*D22 -> 0 | H22: =$C22*E22 -> 800 | I22: =$C22*F22 -> 1800 | J22: Month 1 | K22: Account verification, payout setup, listing template build.
A23: B5 | B23: Business email, Google Workspace & cloud drive setup | C23: 1 | D23: 300 | E23: 600 | F23: 1200 | G23: =$C23*D23 -> 300 | H23: =$C23*E23 -> 600 | I23: =$C23*F23 -> 1200 | J23: Month 1 | K23: One-off configuration. Seat licences are OPEX.
A24: B6 | B24: Accounting system setup & chart of accounts (Zoho Books / Xero) | C24: 1 | D24: 800 | E24: 1500 | F24: 3000 | G24: =$C24*D24 -> 800 | H24: =$C24*E24 -> 1500 | I24: =$C24*F24 -> 3000 | J24: Month 1 | K24: VAT-compliant chart of accounts. Doing this properly now avoids a costly first-audit clean-up.
A25: B7 | B25: AI workspace setup — prompt library, SOP automation, guest-messaging templates | C25: 1 | D25: 0 | E25: 1500 | F25: 4000 | G25: =$C25*D25 -> 0 | H25: =$C25*E25 -> 1500 | I25: =$C25*F25 -> 4000 | J25: Month 1–2 | K25: One-off build of the AI operating layer. The recurring subscription cost sits in OPEX per management item 5.
A26: C. BRAND & MARKETING SETUP
A27: C1 | B27: Brand identity — logo, typography, Japanese-inspired visual system | C27: 1 | D27: 2500 | E27: 4500 | F27: 9000 | G27: =$C27*D27 -> 2500 | H27: =$C27*E27 -> 4500 | I27: =$C27*F27 -> 9000 | J27: Month 1 | K27: Supports the Ma / Shibui / Bushido / Wabi-Sabi brand philosophy in the Business Profile.
A28: C2 | B28: Brand photography & short-form video (company level, not per unit) | C28: 1 | D28: 2000 | E28: 3500 | F28: 7000 | G28: =$C28*D28 -> 2000 | H28: =$C28*E28 -> 3500 | I28: =$C28*F28 -> 7000 | J28: Month 1–2 | K28: Used across the website, OTA profile and owner pitch deck.
A29: C3 | B29: Owner acquisition pitch deck & management-contract pack | C29: 1 | D29: 800 | E29: 1800 | F29: 3500 | G29: =$C29*D29 -> 800 | H29: =$C29*E29 -> 1800 | I29: =$C29*F29 -> 3500 | J29: Month 1 | K29: The core sales asset for the marketing team in both Option 1 and Option 2.
A30: C4 | B30: Printed collateral, business cards, owner welcome pack | C30: 1 | D30: 400 | E30: 900 | F30: 1800 | G30: =$C30*D30 -> 400 | H30: =$C30*E30 -> 900 | I30: =$C30*F30 -> 1800 | J30: Month 1
A31: C5 | B31: Social media profile setup & launch content batch | C31: 1 | D31: 500 | E31: 1200 | F31: 2500 | G31: =$C31*D31 -> 500 | H31: =$C31*E31 -> 1200 | I31: =$C31*F31 -> 2500 | J31: Month 1
A32: D. OFFICE EQUIPMENT & FURNITURE (DUBAI)
A33: D1 | B33: Laptop — operations | C33: 2 | D33: 2800 | E33: 3800 | F33: 5500 | G33: =$C33*D33 -> 5600 | H33: =$C33*E33 -> 7600 | I33: =$C33*F33 -> 11000 | J33: Month 1 | K33: One for the operations & service staff member, one for management.
A34: D2 | B34: Mobile handset — dedicated 24/7 guest support line | C34: 1 | D34: 1200 | E34: 1900 | F34: 3200 | G34: =$C34*D34 -> 1200 | H34: =$C34*E34 -> 1900 | I34: =$C34*F34 -> 3200 | J34: Month 1 | K34: The Business Profile promises 24/7 guest support. It needs its own line and device.
A35: D3 | B35: Printer / scanner (contracts, DET paperwork) | C35: 1 | D35: 500 | E35: 850 | F35: 1500 | G35: =$C35*D35 -> 500 | H35: =$C35*E35 -> 850 | I35: =$C35*F35 -> 1500 | J35: Month 1
A36: D4 | B36: Office desk, chairs & storage | C36: 1 | D36: 1800 | E36: 3200 | F36: 6000 | G36: =$C36*D36 -> 1800 | H36: =$C36*E36 -> 3200 | I36: =$C36*F36 -> 6000 | J36: Month 1
A37: D5 | B37: Key-safe cabinet & spare-key management system | C37: 1 | D37: 500 | E37: 900 | F37: 1600 | G37: =$C37*D37 -> 500 | H37: =$C37*E37 -> 900 | I37: =$C37*F37 -> 1600 | J37: Month 1 | K37: Physical key control across a multi-unit portfolio. An audit point for owners.
A38: D6 | B38: Router, networking & basic office IT | C38: 1 | D38: 300 | E38: 550 | F38: 1000 | G38: =$C38*D38 -> 300 | H38: =$C38*E38 -> 550 | I38: =$C38*F38 -> 1000 | J38: Month 1
A39: E. DEPOSITS & PREPAYMENTS
A40: E1 | B40: Office rent security deposit (refundable) | C40: 1 | D40: 2500 | E40: 5000 | F40: 9000 | G40: =$C40*D40 -> 2500 | H40: =$C40*E40 -> 5000 | I40: =$C40*F40 -> 9000 | J40: Month 1 | K40: Refundable at lease end. Cash out on day one.
A41: E2 | B41: DEWA office connection deposit (refundable) | C41: 1 | D41: 1000 | E41: 2000 | F41: 3500 | G41: =$C41*D41 -> 1000 | H41: =$C41*E41 -> 2000 | I41: =$C41*F41 -> 3500 | J41: Month 1 | K41: Refundable.
...

Sheet Unit Setup (1 Unit)
A1: UNIT SETUP CAPEX — COST TO BRING ONE UNIT LIVE
A2: Commission-only model: the owner supplies the furnished apartment. Orizuru funds only the operating layer.
A4: Ref | B4: Line item | C4: Qty | D4: Unit cost — Low | E4: Unit cost — Base | F4: Unit cost — High | G4: Total — Base | H4: Basis / note
A5: U1 | B5: DET holiday-home permit — first issue (per unit, per year) | C5: 1 | D5: 1200 | E5: 1520 | F5: 1800 | G5: =C5*E5 -> 1520 | H5: Dubai Dept. of Economy & Tourism per-unit permit. Usually re-charged to the owner — confirm in the management contract.
A6: U2 | B6: Smart lock / keyless entry device + install | C6: 1 | D6: 850 | E6: 1200 | F6: 1700 | G6: =C6*E6 -> 1200 | H6: Essential for self check-in. Removes the cost of a physical key handover per booking.
A7: U3 | B7: Professional listing photography (unit) | C7: 1 | D7: 500 | E7: 800 | F7: 1400 | G7: =C7*E7 -> 800 | H7: Single biggest driver of conversion on Airbnb / Booking.com. Do not economise here.
A8: U4 | B8: Linen & towel par stock — 3 sets | C8: 1 | D8: 1100 | E8: 1800 | F8: 2600 | G8: =C8*E8 -> 1800 | H8: 3 sets allows one in use, one in laundry, one on the shelf. Required for same-day turnovers.
A9: U5 | B9: Welcome & amenity kit (branded, Japanese-hospitality standard) | C9: 1 | D9: 300 | E9: 450 | F9: 700 | G9: =C9*E9 -> 450 | H9: Brand differentiator per the Ma / Shibui positioning in the Business Profile.
A10: U6 | B10: Safety kit — smoke detector, fire extinguisher, first-aid box | C10: 1 | D10: 380 | E10: 550 | F10: 800 | G10: =C10*E10 -> 550 | H10: DET holiday-home inspection requirement.
A11: U7 | B11: Small appliances & inventory top-up (kettle, iron, hairdryer, crockery gaps) | C11: 1 | D11: 500 | E11: 900 | F11: 1600 | G11: =C11*E11 -> 900 | H11: Covers the gap between what the owner supplies and DET / guest expectation.
A12: U8 | B12: Initial deep clean & staging before first listing | C12: 1 | D12: 400 | E12: 600 | F12: 950 | G12: =C12*E12 -> 600 | H12: One-off. Routine turnover cleaning sits in OPEX.
A13: U9 | B13: Inventory & condition report, listing build, channel sync | C13: 1 | D13: 200 | E13: 300 | F13: 500 | G13: =C13*E13 -> 300 | H13: Protects against damage disputes and is the baseline for owner reporting.
A14: U10 | B14: Guest welcome book, house rules, signage (printed) | C14: 1 | D14: 120 | E14: 200 | F14: 350 | G14: =C14*E14 -> 200 | H14: Reduces avoidable guest-support contacts.
B15: Subtotal — per unit | D15: =SUMPRODUCT($C$5:$C$14,D5:D14) -> 5550 | E15: =SUMPRODUCT($C$5:$C$14,E5:E14) -> 8320 | F15: =SUMPRODUCT($C$5:$C$14,F5:F14) -> 12400 | G15: =SUM(G5:G14) -> 8320
B16: Contingency | C16: 0.1 | D16: =D15*$C$16 -> 555 | E16: =E15*$C$16 -> 832 | F16: =F15*$C$16 -> 1240 | G16: =G15*$C$16 -> 832 | H16: Applied to the per-unit subtotal. Covers price movement on permits and hardware.
B17: TOTAL CAPEX PER UNIT | D17: =D15+D16 -> 6105 | E17: =E15+E16 -> 9152 | F17: =F15+F16 -> 13640 | G17: =G15+G16 -> 9152
A20: PORTFOLIO SCALING REFERENCE — FOR INFORMATION ONLY, NOT INCLUDED IN THE CAPEX TOTAL
A21: Per management, the CAPEX total is built for ONE unit. This table shows what the same unit-setup cost becomes at portfolio scale, against the Business Profile's 70–80 unit Year-1 target.
A23: Units | B23: Total — Low | C23: Total — Base | D23: Total — High
A24: 1 | B24: =$A24*D$17 -> 6105 | C24: =$A24*E$17 -> 9152 | D24: =$A24*F$17 -> 13640
A25: 5 | B25: =$A25*D$17 -> 30525 | C25: =$A25*E$17 -> 45760 | D25: =$A25*F$17 -> 68200
A26: 10 | B26: =$A26*D$17 -> 61050 | C26: =$A26*E$17 -> 91520 | D26: =$A26*F$17 -> 136400
A27: 25 | B27: =$A27*D$17 -> 152625 | C27: =$A27*E$17 -> 228800 | D27: =$A27*F$17 -> 341000
A28: 50 | B28: =$A28*D$17 -> 305250 | C28: =$A28*E$17 -> 457600 | D28: =$A28*F$17 -> 682000
A29: 80 | B29: =$A29*D$17 -> 488400 | C29: =$A29*E$17 -> 732160 | D29: =$A29*F$17 -> 1091200

Sheet OPEX Summary
A1: OPEX SUMMARY — YEAR 1
A2: All figures AED. Reads live from 'OPEX Monthly'. Change the scenario on the Assumptions tab to re-cut it.
A4: Category | B4: FY1 total | C4: Monthly average | D4: % of total OPEX | F4: Comment
A5: A. STAFF COSTS | B5: ='OPEX Monthly'!O22 -> 64242 | C5: =B5/12 -> 5353.5 | D5: =IF($B$14=0,0,B5/$B$14) -> 0.090007816 | F5: Headcount now scales with the portfolio (see the staffing ratio on Assumptions). Still understated: directors work unpaid.
A6: B. Marketing — Option 1 (fully online) | B6: ='OPEX Monthly'!O29 -> 7760 | C6: =B6/12 -> 646.66667 | D6: =IF($B$14=0,0,B6/$B$14) -> 0.010872337 | F6: Runs M1–M2 only unless adopted from M3 on the Assumptions tab.
A7: C. Marketing — Option 2 (remote office) | B7: ='OPEX Monthly'!O38 -> 57300 | C7: =B7/12 -> 4775 | D7: =IF($B$14=0,0,B7/$B$14) -> 0.080281558 | F7: Runs M1–M2 only unless adopted from M3 on the Assumptions tab.
A8: D. Unit-acquisition commission (2%) | B8: ='OPEX Monthly'!O42 -> 75103.2 | C8: =B8/12 -> 6258.6 | D8: =IF($B$14=0,0,B8/$B$14) -> 0.10522516 | F8: Grows every month as the portfolio grows — this is the line that scales fastest of anything here.
A9: E. TECHNOLOGY, PLATFORM & AI | B9: ='OPEX Monthly'!O53 -> 70331.13 | C9: =B9/12 -> 5860.9275 | D9: =IF($B$14=0,0,B9/$B$14) -> 0.09853914 | F9: Part fixed (AI, Workspace, website), part per-unit (PMS, pricing, locks). Includes the AI subscriptions specified by management.
A10: F. UNIT OPERATIONS | B10: ='OPEX Monthly'!O61 -> 196420 | C10: =B10/12 -> 16368.333 | D10: =IF($B$14=0,0,B10/$B$14) -> 0.27519902 | F10: Fully variable. Much of it is re-chargeable to owners or guests — set the relevant assumptions to 0 if you recharge.
A11: G. OFFICE & ADMINISTRATION | B11: ='OPEX Monthly'!O71 -> 154694.16 | C11: =B11/12 -> 12891.18 | D11: =IF($B$14=0,0,B11/$B$14) -> 0.21673801 | F11: Mostly fixed. Transport is the one line that climbs with unit count.
A12: H. PROFESSIONAL, COMPLIANCE & INSURANCE | B12: ='OPEX Monthly'!O82 -> 53900 | C12: =B12/12 -> 4491.6667 | D12: =IF($B$14=0,0,B12/$B$14) -> 0.075517906 | F12: Annual costs accrued monthly so no single month takes the hit. Non-negotiable for a licensed UAE entity.
A13: Contingency | B13: ='OPEX Monthly'!O86 -> 33987.524 | C13: =B13/12 -> 2832.2937 | D13: =IF($B$14=0,0,B13/$B$14) -> 0.047619048 | F13: Set on the Assumptions tab.
A14: TOTAL OPEX — YEAR 1 | B14: =SUM(B5:B13) -> 713738.01 | C14: =B14/12 -> 59478.168 | D14: =IF($B$14=0,0,SUM(D5:D13)) -> 1
A16: KEY METRICS — YEAR 1
A17: Units signed by end of Year 1 | B17: ='OPEX Monthly'!N8 -> 80 | F17: Against the Business Profile's 70–80 unit Year-1 target.
A18: Gross booking revenue (portfolio, guest spend) | B18: ='OPEX Monthly'!O11 -> 3755160 | F18: This is what guests pay across the portfolio — NOT Orizuru's revenue.
A19: Orizuru revenue (management fees) | B19: ='OPEX Monthly'!O12 -> 751032 | F19: Orizuru's actual top line under the commission-only model.
A20: Total OPEX | B20: =B14 -> 713738.01
A21: Operating surplus / (deficit) | B21: ='OPEX Monthly'!O92 -> 37293.986 | F21: Before corporate tax and before any director remuneration.
A22: Peak cash requirement (worst cumulative month) | B22: =MIN('OPEX Monthly'!C93:N93) -> -76726.005 | F22: The most negative the cumulative operating cash position ever gets. THIS is the working capital number to fund — not the annual OPEX figure.
A23: OPEX as % of Orizuru revenue | B23: =IF(B19=0,0,B20/B19) -> 0.95034301 | F23: Total OPEX divided by Orizuru's management fee revenue. Above 100% means Year 1 runs at a loss — normal while the portfolio ramps.
A24: Exit-run-rate monthly OPEX (Month 12) | B24: ='OPEX Monthly'!N87 -> 113117.82 | F24: The steady-state monthly cost you carry into Year 2.
A25: OPEX per live unit at Month 12 | B25: ='OPEX Monthly'!N95 -> 1593.2087 | F25: Efficiency measure. Should fall steadily as the portfolio grows.
A27: WHAT I ADDED THAT WAS NOT IN YOUR BRIEF — AND WHY
A28: • Staff visa, medical insurance, Emirates ID and end-of-service gratuity. AED 3,000/month is the salary, not the cost of employing someone in the UAE. The true loaded cost is roughly 45–50% higher.
A29: • Trade licence and DET operator permit renewal, accrued monthly. These arrive as a single large annual bill and sink first-year cash plans that ignored them.
A30: • Public liability and professional indemnity insurance. Orizuru holds keys to other people's property — this is not optional.
A31: • External audit and Corporate Tax compliance. UAE Corporate Tax applies above AED 375,000 of taxable profit; the compliance cost applies regardless.
A32: • Transport, fuel, Salik and parking. Check-ins and inspections across Dubai at 70–80 units. Consistently the most underestimated line in holiday-home management.
A33: • Per-unit software: PMS/channel manager, dynamic pricing, smart-lock platform. These are priced per property, so they scale with the portfolio and are easy to miss when modelling a single unit.
A34: • For Option 2: local utilities, an on-site supervisor, and a compliant offshore contracting route. A room with 4–6 people in it costs more than rent plus wages.
A35: • Contingency. First-year UAE service company with regulatory fees in motion.
A37: THREE THINGS TO LOOK AT BEFORE YOU CIRCULATE THIS
A38: • STAFFING NOW SCALES WITH THE PORTFOLIO. Headcount is driven by the 'live units per operations staff member' ratio on the Assumptions tab (35 in the Base case), with a floor of one person. The team grows through Year 1 as units come live rather than staying at one person for 80 units, which was never realistic. Tighten or loosen the ratio there — it is the single input that decides staff cost.
A39: • REVENUE RECOGNITION vs THE BUSINESS PROFILE. The profile projects AED 2.5–4.5M Year-1 turnover. Under a pure commission-only model at 70–80 units, Orizuru's own revenue is materially lower — the AED 2.5–4.5M is closer to gross booking value passing through. Agree with your accountant and the bank which figure you are presenting before submission; they are very different numbers.
A40: • THE 2% IS ONGOING, NOT ONE-OFF. As instructed, it applies to every live unit every month, forever. By Month 12 it is one of the larger single lines in the model and it never stops growing. If the intent was a one-off signing incentive, tell me and I will re-cut it — the difference over three years is very large.

Sheet OPEX Monthly
A1: OPEX — MONTH BY MONTH, YEAR 1
A2: All figures AED. Commission-only model: no unit rent, no owner utilities. Driven entirely by the Assumptions tab — change the scenario there and this whole sheet moves.
A4: Line item | B4: Basis | C4: M1 | D4: M2 | E4: M3 | F4: M4 | G4: M5 | H4: M6 | I4: M7 | J4: M8 | K4: M9 | L4: M10 | M4: M11 | N4: M12 | O4: FY1 TOTAL | P4: % of OPEX
A5: DRIVERS — edit the yellow ramp row to change the whole model
A6: Month number | C6: 1 | D6: 2 | E6: 3 | F6: 4 | G6: 5 | H6: 6 | I6: 7 | J6: 8 | K6: 9 | L6: 10 | M6: 11 | N6: 12
A7: New units signed in month | B7: Input — editable | C7: 3 | D7: 4 | E7: 5 | F7: 6 | G7: 6 | H7: 7 | I7: 7 | J7: 8 | K7: 8 | L7: 8 | M7: 9 | N7: 9 | O7: =SUM(C7:N7) -> 80
A8: Cumulative units signed | B8: Running total | C8: =C7 -> 3 | D8: =C8+D7 -> 7 | E8: =D8+E7 -> 12 | F8: =E8+F7 -> 18 | G8: =F8+G7 -> 24 | H8: =G8+H7 -> 31 | I8: =H8+I7 -> 38 | J8: =I8+J7 -> 46 | K8: =J8+K7 -> 54 | ... N8: =M8+N7 -> 80 | O8: =N8 -> 80
A9: Live revenue-generating units | B9: 1-month onboarding lag | C9: 0 | D9: =C8 -> 3 | E9: =D8 -> 7 | F9: =E8 -> 12 | G9: =F8 -> 18 | H9: =G8 -> 24 | I9: =H8 -> 31 | J9: =I8 -> 38 | K9: =J8 -> 46 | ... N9: =M8 -> 71 | O9: =N9 -> 71
A10: Operations headcount required | B10: Max(minimum, live units / ratio) | C10: =MAX(Assumptions!$F$19,ROUNDUP(C9/Assumptions!$F$20,0)) -> 1 | D10: =MAX(Assumptions!$F$19,ROUNDUP(D9/Assumptions!$F$20,0)) -> 1 | E10: =MAX(Assumptions!$F$19,ROUNDUP(E9/Assumptions!$F$20,0)) -> 1 | F10: =MAX(Assumptions!$F$19,ROUNDUP(F9/Assumptions!$F$20,0)) -> 1 | G10: =MAX(Assumptions!$F$19,ROUNDUP(G9/Assumptions!$F$20,0)) -> 1 | H10: =MAX(Assumptions!$F$19,ROUNDUP(H9/Assumptions!$F$20,0)) -> 1 | I10: =MAX(Assumptions!$F$19,ROUNDUP(I9/Assumptions!$F$20,0)) -> 1 | J10: =MAX(Assumptions!$F$19,ROUNDUP(J9/Assumptions!$F$20,0)) -> 2 | ... N10: =MAX(Assumptions!$F$19,ROUNDUP(N9/Assumptions!$F$20,0)) -> 3 | O10: =AVERAGE(C10:N10) -> 1.5
A11: Gross booking revenue (portfolio) | B11: Live units x gross rev/unit | C11: =C9*Assumptions!$F$14 -> 0 | D11: =D9*Assumptions!$F$14 -> 30780 | E11: =E9*Assumptions!$F$14 -> 71820 | F11: =F9*Assumptions!$F$14 -> 123120 | G11: =G9*Assumptions!$F$14 -> 184680 | H11: =H9*Assumptions!$F$14 -> 246240 | I11: =I9*Assumptions!$F$14 -> 318060 | J11: =J9*Assumptions!$F$14 -> 389880 | ... N11: =N9*Assumptions!$F$14 -> 728460 | O11: =SUM(C11:N11) -> 3755160
A12: Orizuru management fee revenue | B12: Gross x management fee % | C12: =C11*Assumptions!$F$15 -> 0 | D12: =D11*Assumptions!$F$15 -> 6156 | E12: =E11*Assumptions!$F$15 -> 14364 | F12: =F11*Assumptions!$F$15 -> 24624 | G12: =G11*Assumptions!$F$15 -> 36936 | H12: =H11*Assumptions!$F$15 -> 49248 | I12: =I11*Assumptions!$F$15 -> 63612 | J12: =J11*Assumptions!$F$15 -> 77976 | ... N12: =N11*Assumptions!$F$15 -> 145692 | O12: =SUM(C12:N12) -> 751032
A13: Option 1 active (1/0) | B13: Both run M1–M2 per management | C13: =IF(OR(C6<=Assumptions!$B$7,Assumptions!$B$6="Option 1",Assumptions!$B$6="Both"),1,0) -> 1 | D13: =IF(OR(D6<=Assumptions!$B$7,Assumptions!$B$6="Option 1",Assumptions!$B$6="Both"),1,0) -> 1 | E13: =IF(OR(E6<=Assumptions!$B$7,Assumptions!$B$6="Option 1",Assumptions!$B$6="Both"),1,0) -> 0 | F13: =IF(OR(F6<=Assumptions!$B$7,Assumptions!$B$6="Option 1",Assumptions!$B$6="Both"),1,0) -> 0 | G13: =IF(OR(G6<=Assumptions!$B$7,Assumptions!$B$6="Option 1",Assumptions!$B$6="Both"),1,0) -> 0 | H13: =IF(OR(H6<=Assumptions!$B$7,Assumptions!$B$6="Option 1",Assumptions!$B$6="Both"),1,0) -> 0 | I13: =IF(OR(I6<=Assumptions!$B$7,Assumptions!$B$6="Option 1",Assumptions!$B$6="Both"),1,0) -> 0 | J13: =IF(OR(J6<=Assumptions!$B$7,Assumptions!$B$6="Option 1",Assumptions!$B$6="Both"),1,0) -> 0 | ... N13: =IF(OR(N6<=Assumptions!$B$7,Assumptions!$B$6="Option 1",Assumptions!$B$6="Both"),1,0) -> 0
A14: Option 2 active (1/0) | B14: Both run M1–M2 per management | C14: =IF(OR(C6<=Assumptions!$B$7,Assumptions!$B$6="Option 2",Assumptions!$B$6="Both"),1,0) -> 1 | D14: =IF(OR(D6<=Assumptions!$B$7,Assumptions!$B$6="Option 2",Assumptions!$B$6="Both"),1,0) -> 1 | E14: =IF(OR(E6<=Assumptions!$B$7,Assumptions!$B$6="Option 2",Assumptions!$B$6="Both"),1,0) -> 1 | F14: =IF(OR(F6<=Assumptions!$B$7,Assumptions!$B$6="Option 2",Assumptions!$B$6="Both"),1,0) -> 1 | G14: =IF(OR(G6<=Assumptions!$B$7,Assumptions!$B$6="Option 2",Assumptions!$B$6="Both"),1,0) -> 1 | H14: =IF(OR(H6<=Assumptions!$B$7,Assumptions!$B$6="Option 2",Assumptions!$B$6="Both"),1,0) -> 1 | I14: =IF(OR(I6<=Assumptions!$B$7,Assumptions!$B$6="Option 2",Assumptions!$B$6="Both"),1,0) -> 1 | J14: =IF(OR(J6<=Assumptions!$B$7,Assumptions!$B$6="Option 2",Assumptions!$B$6="Both"),1,0) -> 1 | ... N14: =IF(OR(N6<=Assumptions!$B$7,Assumptions!$B$6="Option 2",Assumptions!$B$6="Both"),1,0) -> 1
A16: A. STAFF COSTS — DUBAI
A17: Directors' salary | B17: Per management — nil | C17: =Assumptions!$F$18 -> 0 | D17: =Assumptions!$F$18 -> 0 | E17: =Assumptions!$F$18 -> 0 | F17: =Assumptions!$F$18 -> 0 | G17: =Assumptions!$F$18 -> 0 | H17: =Assumptions!$F$18 -> 0 | I17: =Assumptions!$F$18 -> 0 | J17: =Assumptions!$F$18 -> 0 | ... N17: =Assumptions!$F$18 -> 0 | O17: =SUM(C17:N17) -> 0
A18: Operations & service staff | B18: Headcount x AED 3,000, scaling with units | C18: =C10*Assumptions!$F$21 -> 3000 | D18: =D10*Assumptions!$F$21 -> 3000 | E18: =E10*Assumptions!$F$21 -> 3000 | F18: =F10*Assumptions!$F$21 -> 3000 | G18: =G10*Assumptions!$F$21 -> 3000 | H18: =H10*Assumptions!$F$21 -> 3000 | I18: =I10*Assumptions!$F$21 -> 3000 | J18: =J10*Assumptions!$F$21 -> 6000 | ... N18: =N10*Assumptions!$F$21 -> 9000 | O18: =SUM(C18:N18) -> 54000
A19: Staff visa, medical insurance & EID (accrual) | B19: Per UAE employee | C19: =C10*Assumptions!$F$22 -> 380 | D19: =D10*Assumptions!$F$22 -> 380 | E19: =E10*Assumptions!$F$22 -> 380 | F19: =F10*Assumptions!$F$22 -> 380 | G19: =G10*Assumptions!$F$22 -> 380 | H19: =H10*Assumptions!$F$22 -> 380 | I19: =I10*Assumptions!$F$22 -> 380 | J19: =J10*Assumptions!$F$22 -> 760 | ... N19: =N10*Assumptions!$F$22 -> 1140 | O19: =SUM(C19:N19) -> 6840
A20: End-of-service gratuity accrual | B20: 5.8% of salary | C20: =C18*Assumptions!$F$23 -> 174 | D20: =D18*Assumptions!$F$23 -> 174 | E20: =E18*Assumptions!$F$23 -> 174 | F20: =F18*Assumptions!$F$23 -> 174 | G20: =G18*Assumptions!$F$23 -> 174 | H20: =H18*Assumptions!$F$23 -> 174 | I20: =I18*Assumptions!$F$23 -> 174 | J20: =J18*Assumptions!$F$23 -> 348 | ... N20: =N18*Assumptions!$F$23 -> 522 | O20: =SUM(C20:N20) -> 3132
A21: WPS / payroll processing | B21: Per employee | C21: =C10*Assumptions!$F$24 -> 15 | D21: =D10*Assumptions!$F$24 -> 15 | E21: =E10*Assumptions!$F$24 -> 15 | F21: =F10*Assumptions!$F$24 -> 15 | G21: =G10*Assumptions!$F$24 -> 15 | H21: =H10*Assumptions!$F$24 -> 15 | I21: =I10*Assumptions!$F$24 -> 15 | J21: =J10*Assumptions!$F$24 -> 30 | ... N21: =N10*Assumptions!$F$24 -> 45 | O21: =SUM(C21:N21) -> 270
A22: TOTAL STAFF COSTS | C22: =SUM(C17:C21) -> 3569 | D22: =SUM(D17:D21) -> 3569 | E22: =SUM(E17:E21) -> 3569 | F22: =SUM(F17:F21) -> 3569 | G22: =SUM(G17:G21) -> 3569 | H22: =SUM(H17:H21) -> 3569 | I22: =SUM(I17:I21) -> 3569 | J22: =SUM(J17:J21) -> 7138 | ... N22: =SUM(N17:N21) -> 10707 | O22: =SUM(C22:N22) -> 64242 | P22: =IF($O$87=0,0,$O22/$O$87) -> 0.090007816
A24: B. MARKETING — OPTION 1: FULLY ONLINE (switches off after M2 unless adopted)
A25: Option 1 — team cost | B25: Headcount x rate | C25: =C13*Assumptions!$F$26*Assumptions!$F$27 -> 1800 | D25: =D13*Assumptions!$F$26*Assumptions!$F$27 -> 1800 | E25: =E13*Assumptions!$F$26*Assumptions!$F$27 -> 0 | F25: =F13*Assumptions!$F$26*Assumptions!$F$27 -> 0 | G25: =G13*Assumptions!$F$26*Assumptions!$F$27 -> 0 | H25: =H13*Assumptions!$F$26*Assumptions!$F$27 -> 0 | I25: =I13*Assumptions!$F$26*Assumptions!$F$27 -> 0 | J25: =J13*Assumptions!$F$26*Assumptions!$F$27 -> 0 | ... N25: =N13*Assumptions!$F$26*Assumptions!$F$27 -> 0 | O25: =SUM(C25:N25) -> 3600
A26: Option 1 — digital ads & lead generation | C26: =C13*Assumptions!$F$28 -> 1500 | D26: =D13*Assumptions!$F$28 -> 1500 | E26: =E13*Assumptions!$F$28 -> 0 | F26: =F13*Assumptions!$F$28 -> 0 | G26: =G13*Assumptions!$F$28 -> 0 | H26: =H13*Assumptions!$F$28 -> 0 | I26: =I13*Assumptions!$F$28 -> 0 | J26: =J13*Assumptions!$F$28 -> 0 | ... N26: =N13*Assumptions!$F$28 -> 0 | O26: =SUM(C26:N26) -> 3000
A27: Option 1 — outreach tooling & CRM | C27: =C13*Assumptions!$F$29 -> 280 | D27: =D13*Assumptions!$F$29 -> 280 | E27: =E13*Assumptions!$F$29 -> 0 | F27: =F13*Assumptions!$F$29 -> 0 | G27: =G13*Assumptions!$F$29 -> 0 | H27: =H13*Assumptions!$F$29 -> 0 | I27: =I13*Assumptions!$F$29 -> 0 | J27: =J13*Assumptions!$F$29 -> 0 | ... N27: =N13*Assumptions!$F$29 -> 0 | O27: =SUM(C27:N27) -> 560
