Workbook

Sheet README
A1: ORIZURU HOLIDAY HOMES LLC — OPERATING EXPENDITURE (OPEX)
A2: Dubai, UAE | Trade Licence 1634278 | 12-month monthly model | All figures in AED
A4: HOW TO USE THIS WORKBOOK
A5: Tab | B5: What it does
A6: Assumptions | B6: Every input, at Low / Base / High. Set the SCENARIO cell (B4) and the whole model re-cuts. Set 'Option adopted from Month 3' (B6) to switch marketing options.
A7: OPEX Summary | B7: One-page Year-1 view: category totals, key metrics, and the notes you should read first.
A8: OPEX Monthly | B8: The model. 12 months across, every cost line down. Edit the yellow unit-ramp row to change the growth path.
A9: Marketing Comparison | B9: Option 1 vs Option 2 head-to-head, plus what to measure before deciding in Month 3.
A10: AI Subscriptions | B10: HJ item 5 broken out tool by tool. Feeds the AI line in the model.
A12: THE FOUR LEVERS THAT MOVE EVERYTHING
A13: 1. | B13: Assumptions!B4 — SCENARIO (Low / Base / High).
A14: 2. | B14: Assumptions!B6 — which marketing option is adopted from Month 3 (or 'Both' to keep running in parallel).
A15: 3. | B15: OPEX Monthly, yellow row — new units signed each month. Currently ramps to 80 units by Month 12, matching the Business Profile's 70–80 target. Set every month to 0 except M1=1 for a single-unit view.
A16: 4. | B16: Assumptions!F column — the active value of any individual line. Override any single input directly in its Low/Base/High cells.
A18: MODEL BASIS — CONFIRMED WITH HJ
A19: • | B19: PURE MANAGEMENT / COMMISSION-ONLY. Orizuru does not master-lease. There is NO unit rent, no unit DEWA and no unit internet anywhere in this OPEX — those costs sit with the property owner.
A20: • | B20: Directors draw NO salary.
A21: • | B21: Operations & service staff: 1 person at AED 3,000/month.
A22: • | B22: Both marketing options run in parallel for Months 1–2, then one is adopted.
A23: • | B23: The 2% per signed unit is an ONGOING trailing commission on that unit's monthly revenue, applied every month for as long as the unit is live.
A24: • | B24: AI subscriptions are broken out on their own tab.
A25: • | B25: Domain (AED 387, 3 years) and company stamp (AED 137) are ONE-OFF costs and sit in the CAPEX workbook, not here.
A27: COLOUR LEGEND
A28: Blue text | B28: Hardcoded input — edit freely.
A29: Yellow fill | B29: Key lever, or a figure supplied by HJ.
A30: Black text | B30: Formula. Do not overwrite.
A31: Green text | B31: Link to another sheet in this workbook.
A33: WHAT IS DELIBERATELY NOT IN HERE
A34: • | B34: OTA commission (Airbnb / Booking.com, 15–18%). Under a commission-only model this is deducted from gross booking revenue before the owner's split — it is not an Orizuru operating cost. Add it only if your management contracts make Orizuru bear it.
A35: • | B35: Tourism Dirham. Collected from the guest and remitted to DET. Pure pass-through.
A36: • | B36: Corporate Tax itself (9% above AED 375,000 taxable profit). It is a tax on profit, not OPEX. The compliance/filing cost IS included.
A37: • | B37: Depreciation on the CAPEX. Non-cash — belongs in the P&L, not in an OPEX cash budget.
A38: • | B38: Unit furnishing and setup. Owner-funded under this model; the operating layer Orizuru does fund is in the CAPEX workbook.

Sheet Assumptions
A1: OPEX ASSUMPTIONS — ORIZURU HOLIDAY HOMES LLC
A2: All figures AED unless stated. Blue = editable input. Yellow = figure supplied by HJ or a key lever.
A4: SCENARIO | B4: Base | C4: Change this cell to Low / Base / High. Every 'Active' figure below and the whole monthly model follow it. | J4: Low
A5: Scenario index | B5: =MATCH($B$4,$J$4:$J$6,0) | J5: Base
A6: Option adopted from Month 3 | B6: Option 2 | C6: Both options run in Months 1–2 per HJ. From Month 3 the model keeps whichever you select here. Select 'Both' to keep running them in parallel all year. | J6: High
A7: Parallel-run months | B7: 2 | C7: Per HJ: run both marketing options together for the first 2 months to see which works.
A9: Assumption | B9: Unit | C9: Low | D9: Base | E9: High | F9: Active | G9: Source / note
A10: 1. REVENUE DRIVERS — needed to size the 2% commission, gateway fees and cost-to-revenue ratios
A11: Average Daily Rate (ADR) per unit | B11: AED/night | C11: 380 | D11: 450 | E11: 550 | F11: =INDEX(C11:E11,1,Assumptions!$B$5) | G11: Premium 1BR short-term rental, Dubai. Drives the revenue base for the 2% marketing commission.
A12: Occupancy rate | B12: % | C12: 0.65 | D12: 0.75 | E12: 0.82 | F12: =INDEX(C12:E12,1,Assumptions!$B$5) | G12: Dubai holiday-home market runs high; 75% is a realistic stabilised assumption.
A13: Nights per month | B13: nights | C13: 30.4 | D13: 30.4 | E13: 30.4 | F13: =INDEX(C13:E13,1,Assumptions!$B$5) | G13: 365 / 12.
A14: Gross booking revenue per unit per month | B14: AED | C14: =C11*C12*C13 | D14: =D11*D12*D13 | E14: =E11*E12*E13 | F14: =INDEX(C14:E14,1,Assumptions!$B$5) | G14: Calculated. This is the GUEST's spend on that unit — not Orizuru's revenue.
A15: Management fee retained by Orizuru | B15: % of gross | C15: 0.15 | D15: 0.2 | E15: 0.25 | F15: =INDEX(C15:E15,1,Assumptions!$B$5) | G15: Dubai holiday-home management contracts run 15–25%. This IS Orizuru's revenue under the commission-only model.
A16: Orizuru revenue per unit per month | B16: AED | C16: =C14*C15 | D16: =D14*D15 | E16: =E14*E15 | F16: =INDEX(C16:E16,1,Assumptions!$B$5) | G16: Calculated. Compare against the Business Profile's AED 2.5–4.5M turnover target — see the reconciliation note on the README tab.
A17: 2. STAFF — Dubai payroll
A18: Directors' salary | B18: AED/month | C18: 0 | D18: 0 | E18: 0 | F18: =INDEX(C18:E18,1,Assumptions!$B$5) | G18: Per HJ: directors will NOT draw a salary. Note for the bank — this understates the true cost of running the business, since two directors are working unpaid.
A19: Operations & service staff — headcount | B19: persons | C19: 1 | D19: 1 | E19: 1 | F19: =INDEX(C19:E19,1,Assumptions!$B$5) | G19: Per HJ: 1 person.
A20: Operations & service staff — salary | B20: AED/month | C20: 3000 | D20: 3000 | E20: 3000 | F20: =INDEX(C20:E20,1,Assumptions!$B$5) | G20: Per HJ: AED 3,000/month.
A21: Staff visa, medical insurance & EID — monthly accrual per UAE employee | B21: AED/month | C21: 250 | D21: 380 | E21: 550 | F21: =INDEX(C21:E21,1,Assumptions!$B$5) | G21: 2-year residence visa and mandatory Dubai health insurance spread monthly. Real cash cost even though it is billed in lumps.
A22: End-of-service gratuity accrual | B22: % of salary | C22: 0.058 | D22: 0.058 | E22: 0.058 | F22: =INDEX(C22:E22,1,Assumptions!$B$5) | G22: UAE Labour Law: 21 days' basic pay per year of service for the first 5 years = 5.8% of salary. Legally payable — accrue it or it becomes a nasty surprise.
A23: WPS / payroll processing fee | B23: AED/employee/mo | C23: 8 | D23: 15 | E23: 25 | F23: =INDEX(C23:E23,1,Assumptions!$B$5) | G23: Wage Protection System is mandatory for MOHRE-sponsored staff.
A24: 3. MARKETING OPTION 1 — FULLY ONLINE (4 hrs/day)
A25: Team size | B25: persons | C25: 2 | D25: 3 | E25: 4 | F25: =INDEX(C25:E25,1,Assumptions!$B$5) | G25: Per HJ: 2–4 persons.
A26: Cost per person | B26: AED/month | C26: 500 | D26: 600 | E26: 700 | F26: =INDEX(C26:E26,1,Assumptions!$B$5) | G26: Per HJ: AED 500–700 per person.
A27: Digital ads & owner lead generation | B27: AED/month | C27: 800 | D27: 1500 | E27: 2800 | F27: =INDEX(C27:E27,1,Assumptions!$B$5) | G27: A fully-online team without a paid lead flow will stall. This is the cost of feeding them owner leads.
A28: Outreach tooling, CRM & lead database | B28: AED/month | C28: 150 | D28: 280 | E28: 450 | F28: =INDEX(C28:E28,1,Assumptions!$B$5) | G28: LinkedIn Sales Navigator / Property Finder lead access / CRM seats.
A29: Team coordination & QA time | B29: AED/month | C29: 0 | D29: 300 | E29: 600 | F29: =INDEX(C29:E29,1,Assumptions!$B$5) | G29: Someone has to check the work. At 2–4 remote people this is light but not zero.
A30: 4. MARKETING OPTION 2 — REMOTE OFFICE OUTSIDE UAE (4 hrs/day)
A31: Team size | B31: persons | C31: 4 | D31: 5 | E31: 6 | F31: =INDEX(C31:E31,1,Assumptions!$B$5) | G31: Per HJ: 4–6 persons.
A32: Cost per person | B32: AED/month | C32: 180 | D32: 240 | E32: 300 | F32: =INDEX(C32:E32,1,Assumptions!$B$5) | G32: Per HJ: AED 180–300 per person.
A33: Coworking area rent | B33: AED/month | C33: 1350 | D33: 1425 | E33: 1500 | F33: =INDEX(C33:E33,1,Assumptions!$B$5) | G33: Per HJ: AED 1,350–1,500.
A34: Local internet, utilities & equipment | B34: AED/month | C34: 200 | D34: 350 | E34: 550 | F34: =INDEX(C34:E34,1,Assumptions!$B$5) | G34: Not in HJ's original list but unavoidable — a physical room needs connectivity and machines.
A35: On-site supervisor / team lead | B35: AED/month | C35: 0 | D35: 500 | E35: 900 | F35: =INDEX(C35:E35,1,Assumptions!$B$5) | G35: Not in HJ's original list. 4–6 people in a physical room with no supervisor will drift. Recommend keeping this.
A36: Digital ads & lead generation | B36: AED/month | C36: 400 | D36: 900 | E36: 1600 | F36: =INDEX(C36:E36,1,Assumptions!$B$5) | G36: Lower than Option 1 — a larger team does more manual prospecting, so less paid volume is needed.
A37: Local compliance / entity or contractor arrangement | B37: AED/month | C37: 0 | D37: 400 | E37: 900 | F37: =INDEX(C37:E37,1,Assumptions!$B$5) | G37: Not in HJ's original list. Engaging staff outside the UAE needs a compliant contracting route. Flagging it rather than pretending it is free.
A38: 5. UNIT-ACQUISITION COMMISSION — the 2% per HJ
A39: Trailing commission on each signed unit | B39: % | C39: 0.02 | D39: 0.02 | E39: 0.02 | F39: =INDEX(C39:E39,1,Assumptions!$B$5) | G39: Per HJ: 2% for each unit signed, ONGOING on that unit's monthly revenue.
A40: Commission base | B40: — | C40: 1 | D40: 1 | E40: 1 | F40: =INDEX(C40:E40,1,Assumptions!$B$5) | G40: 1 = 2% of the unit's GROSS booking revenue (i.e. c.10% of Orizuru's management fee on that unit). 2 = 2% of Orizuru's management fee only (far cheaper, far weaker incentive). Change the number to switch base.
A41: 6. TECHNOLOGY, PLATFORM & AI
A42: PMS / channel manager licence | B42: AED/unit/mo | C42: 55 | D42: 75 | E42: 95 | F42: =INDEX(C42:E42,1,Assumptions!$B$5) | G42: Hostaway / Guesty style per-property pricing. Scales directly with the portfolio.
...

Sheet OPEX Summary
A1: OPEX SUMMARY — YEAR 1
A2: All figures AED. Reads live from 'OPEX Monthly'. Change the scenario on the Assumptions tab to re-cut it.
A4: Category | B4: FY1 total | C4: Monthly average | D4: % of total OPEX | F4: Comment
A5: A. STAFF COSTS | B5: ='OPEX Monthly'!O21 | C5: =B5/12 | D5: =IF($B$14=0,0,B5/$B$14) | F5: Understated by design: directors work unpaid per HJ. One ops person for a 70–80 unit portfolio is thin — see the notes below.
A6: B. Marketing — Option 1 (fully online) | B6: ='OPEX Monthly'!O28 | C6: =B6/12 | D6: =IF($B$14=0,0,B6/$B$14) | F6: Runs M1–M2 only unless adopted from M3 on the Assumptions tab.
A7: C. Marketing — Option 2 (remote office) | B7: ='OPEX Monthly'!O37 | C7: =B7/12 | D7: =IF($B$14=0,0,B7/$B$14) | F7: Runs M1–M2 only unless adopted from M3 on the Assumptions tab.
A8: D. Unit-acquisition commission (2%) | B8: ='OPEX Monthly'!O41 | C8: =B8/12 | D8: =IF($B$14=0,0,B8/$B$14) | F8: Grows every month as the portfolio grows — this is the line that scales fastest of anything here.
A9: E. TECHNOLOGY, PLATFORM & AI | B9: ='OPEX Monthly'!O52 | C9: =B9/12 | D9: =IF($B$14=0,0,B9/$B$14) | F9: Part fixed (AI, Workspace, website), part per-unit (PMS, pricing, locks). Includes HJ item 5.
A10: F. UNIT OPERATIONS | B10: ='OPEX Monthly'!O60 | C10: =B10/12 | D10: =IF($B$14=0,0,B10/$B$14) | F10: Fully variable. Much of it is re-chargeable to owners or guests — set the relevant assumptions to 0 if you recharge.
A11: G. OFFICE & ADMINISTRATION | B11: ='OPEX Monthly'!O70 | C11: =B11/12 | D11: =IF($B$14=0,0,B11/$B$14) | F11: Mostly fixed. Transport is the one line that climbs with unit count.
A12: H. PROFESSIONAL, COMPLIANCE & INSURANCE | B12: ='OPEX Monthly'!O81 | C12: =B12/12 | D12: =IF($B$14=0,0,B12/$B$14) | F12: Annual costs accrued monthly so no single month takes the hit. Non-negotiable for a licensed UAE entity.
A13: Contingency | B13: ='OPEX Monthly'!O85 | C13: =B13/12 | D13: =IF($B$14=0,0,B13/$B$14) | F13: Set on the Assumptions tab.
A14: TOTAL OPEX — YEAR 1 | B14: =SUM(B5:B13) | C14: =B14/12 | D14: =IF($B$14=0,0,SUM(D5:D13))
A16: KEY METRICS — YEAR 1
A17: Units signed by end of Year 1 | B17: ='OPEX Monthly'!N8 | F17: Against the Business Profile's 70–80 unit Year-1 target.
A18: Gross booking revenue (portfolio, guest spend) | B18: ='OPEX Monthly'!O10 | F18: This is what guests pay across the portfolio — NOT Orizuru's revenue.
A19: Orizuru revenue (management fees) | B19: ='OPEX Monthly'!O11 | F19: Orizuru's actual top line under the commission-only model.
A20: Total OPEX | B20: =B14
A21: Operating surplus / (deficit) | B21: ='OPEX Monthly'!O91 | F21: Before corporate tax and before any director remuneration.
A22: Peak cash requirement (worst cumulative month) | B22: =MIN('OPEX Monthly'!C92:N92) | F22: The most negative the cumulative operating cash position ever gets. THIS is the working capital number to fund — not the annual OPEX figure.
A23: OPEX as % of Orizuru revenue | B23: =IF(B19=0,0,B20/B19) | F23: Total OPEX divided by Orizuru's management fee revenue. Above 100% means Year 1 runs at a loss — normal while the portfolio ramps.
A24: Exit-run-rate monthly OPEX (Month 12) | B24: ='OPEX Monthly'!N86 | F24: The steady-state monthly cost you carry into Year 2.
A25: OPEX per live unit at Month 12 | B25: ='OPEX Monthly'!N94 | F25: Efficiency measure. Should fall steadily as the portfolio grows.
A27: WHAT I ADDED THAT WAS NOT IN YOUR BRIEF — AND WHY
A28: • Staff visa, medical insurance, Emirates ID and end-of-service gratuity. AED 3,000/month is the salary, not the cost of employing someone in the UAE. The true loaded cost is roughly 45–50% higher.
A29: • Trade licence and DET operator permit renewal, accrued monthly. These arrive as a single large annual bill and sink first-year cash plans that ignored them.
A30: • Public liability and professional indemnity insurance. Orizuru holds keys to other people's property — this is not optional.
A31: • External audit and Corporate Tax compliance. UAE Corporate Tax applies above AED 375,000 of taxable profit; the compliance cost applies regardless.
A32: • Transport, fuel, Salik and parking. Check-ins and inspections across Dubai at 70–80 units. Consistently the most underestimated line in holiday-home management.
A33: • Per-unit software: PMS/channel manager, dynamic pricing, smart-lock platform. These are priced per property, so they scale with the portfolio and are easy to miss when modelling a single unit.
A34: • For Option 2: local utilities, an on-site supervisor, and a compliant offshore contracting route. A room with 4–6 people in it costs more than rent plus wages.
A35: • Contingency. First-year UAE service company with regulatory fees in motion.
A37: THREE THINGS TO LOOK AT BEFORE YOU CIRCULATE THIS
A38: • ONE OPERATIONS PERSON FOR 70–80 UNITS IS NOT ENOUGH. At AED 3,000/month you have one person handling check-ins, guest support, housekeeping coordination, maintenance and owner reporting across a portfolio spread over Dubai. Either headcount rises through the year, or check-in and housekeeping get outsourced per unit. The model runs with your figure as instructed — but budget for a second and third hire around Months 4 and 8.
A39: • REVENUE RECOGNITION vs THE BUSINESS PROFILE. The profile projects AED 2.5–4.5M Year-1 turnover. Under a pure commission-only model at 70–80 units, Orizuru's own revenue is materially lower — the AED 2.5–4.5M is closer to gross booking value passing through. Agree with your accountant and the bank which figure you are presenting before submission; they are very different numbers.
A40: • THE 2% IS ONGOING, NOT ONE-OFF. As instructed, it applies to every live unit every month, forever. By Month 12 it is one of the larger single lines in the model and it never stops growing. If the intent was a one-off signing incentive, tell me and I will re-cut it — the difference over three years is very large.

Sheet OPEX Monthly
A1: OPEX — MONTH BY MONTH, YEAR 1
A2: All figures AED. Commission-only model: no unit rent, no owner utilities. Driven entirely by the Assumptions tab — change the scenario there and this whole sheet moves.
A4: Line item | B4: Basis | C4: M1 | D4: M2 | E4: M3 | F4: M4 | G4: M5 | H4: M6 | I4: M7 | J4: M8 | K4: M9 | L4: M10 | M4: M11 | N4: M12 | O4: FY1 TOTAL | P4: % of OPEX
A5: DRIVERS — edit the yellow ramp row to change the whole model
A6: Month number | C6: 1 | D6: 2 | E6: 3 | F6: 4 | G6: 5 | H6: 6 | I6: 7 | J6: 8 | K6: 9 | L6: 10 | M6: 11 | N6: 12
A7: New units signed in month | B7: Input — editable | C7: 3 | D7: 4 | E7: 5 | F7: 6 | G7: 6 | H7: 7 | I7: 7 | J7: 8 | K7: 8 | L7: 8 | M7: 9 | N7: 9 | O7: =SUM(C7:N7)
A8: Cumulative units signed | B8: Running total | C8: =C7 | D8: =C8+D7 | E8: =D8+E7 | F8: =E8+F7 | G8: =F8+G7 | H8: =G8+H7 | I8: =H8+I7 | J8: =I8+J7 | K8: =J8+K7 | ... N8: =M8+N7 | O8: =N8
A9: Live revenue-generating units | B9: 1-month onboarding lag | C9: 0 | D9: =C8 | E9: =D8 | F9: =E8 | G9: =F8 | H9: =G8 | I9: =H8 | J9: =I8 | K9: =J8 | ... N9: =M8 | O9: =N9
A10: Gross booking revenue (portfolio) | B10: Live units x gross rev/unit | C10: =C9*Assumptions!$F$14 | D10: =D9*Assumptions!$F$14 | E10: =E9*Assumptions!$F$14 | F10: =F9*Assumptions!$F$14 | G10: =G9*Assumptions!$F$14 | H10: =H9*Assumptions!$F$14 | I10: =I9*Assumptions!$F$14 | J10: =J9*Assumptions!$F$14 | ... N10: =N9*Assumptions!$F$14 | O10: =SUM(C10:N10)
A11: Orizuru management fee revenue | B11: Gross x management fee % | C11: =C10*Assumptions!$F$15 | D11: =D10*Assumptions!$F$15 | E11: =E10*Assumptions!$F$15 | F11: =F10*Assumptions!$F$15 | G11: =G10*Assumptions!$F$15 | H11: =H10*Assumptions!$F$15 | I11: =I10*Assumptions!$F$15 | J11: =J10*Assumptions!$F$15 | ... N11: =N10*Assumptions!$F$15 | O11: =SUM(C11:N11)
A12: Option 1 active (1/0) | B12: Both run M1–M2 per HJ | C12: =IF(OR(C6<=Assumptions!$B$7,Assumptions!$B$6="Option 1",Assumptions!$B$6="Both"),1,0) | D12: =IF(OR(D6<=Assumptions!$B$7,Assumptions!$B$6="Option 1",Assumptions!$B$6="Both"),1,0) | E12: =IF(OR(E6<=Assumptions!$B$7,Assumptions!$B$6="Option 1",Assumptions!$B$6="Both"),1,0) | F12: =IF(OR(F6<=Assumptions!$B$7,Assumptions!$B$6="Option 1",Assumptions!$B$6="Both"),1,0) | G12: =IF(OR(G6<=Assumptions!$B$7,Assumptions!$B$6="Option 1",Assumptions!$B$6="Both"),1,0) | H12: =IF(OR(H6<=Assumptions!$B$7,Assumptions!$B$6="Option 1",Assumptions!$B$6="Both"),1,0) | I12: =IF(OR(I6<=Assumptions!$B$7,Assumptions!$B$6="Option 1",Assumptions!$B$6="Both"),1,0) | J12: =IF(OR(J6<=Assumptions!$B$7,Assumptions!$B$6="Option 1",Assumptions!$B$6="Both"),1,0) | ... N12: =IF(OR(N6<=Assumptions!$B$7,Assumptions!$B$6="Option 1",Assumptions!$B$6="Both"),1,0)
A13: Option 2 active (1/0) | B13: Both run M1–M2 per HJ | C13: =IF(OR(C6<=Assumptions!$B$7,Assumptions!$B$6="Option 2",Assumptions!$B$6="Both"),1,0) | D13: =IF(OR(D6<=Assumptions!$B$7,Assumptions!$B$6="Option 2",Assumptions!$B$6="Both"),1,0) | E13: =IF(OR(E6<=Assumptions!$B$7,Assumptions!$B$6="Option 2",Assumptions!$B$6="Both"),1,0) | F13: =IF(OR(F6<=Assumptions!$B$7,Assumptions!$B$6="Option 2",Assumptions!$B$6="Both"),1,0) | G13: =IF(OR(G6<=Assumptions!$B$7,Assumptions!$B$6="Option 2",Assumptions!$B$6="Both"),1,0) | H13: =IF(OR(H6<=Assumptions!$B$7,Assumptions!$B$6="Option 2",Assumptions!$B$6="Both"),1,0) | I13: =IF(OR(I6<=Assumptions!$B$7,Assumptions!$B$6="Option 2",Assumptions!$B$6="Both"),1,0) | J13: =IF(OR(J6<=Assumptions!$B$7,Assumptions!$B$6="Option 2",Assumptions!$B$6="Both"),1,0) | ... N13: =IF(OR(N6<=Assumptions!$B$7,Assumptions!$B$6="Option 2",Assumptions!$B$6="Both"),1,0)
A15: A. STAFF COSTS — DUBAI
A16: Directors' salary | B16: Per HJ — nil | C16: =Assumptions!$F$18 | D16: =Assumptions!$F$18 | E16: =Assumptions!$F$18 | F16: =Assumptions!$F$18 | G16: =Assumptions!$F$18 | H16: =Assumptions!$F$18 | I16: =Assumptions!$F$18 | J16: =Assumptions!$F$18 | ... N16: =Assumptions!$F$18 | O16: =SUM(C16:N16)
A17: Operations & service staff | B17: Per HJ — 1 x AED 3,000 | C17: =Assumptions!$F$19*Assumptions!$F$20 | D17: =Assumptions!$F$19*Assumptions!$F$20 | E17: =Assumptions!$F$19*Assumptions!$F$20 | F17: =Assumptions!$F$19*Assumptions!$F$20 | G17: =Assumptions!$F$19*Assumptions!$F$20 | H17: =Assumptions!$F$19*Assumptions!$F$20 | I17: =Assumptions!$F$19*Assumptions!$F$20 | J17: =Assumptions!$F$19*Assumptions!$F$20 | ... N17: =Assumptions!$F$19*Assumptions!$F$20 | O17: =SUM(C17:N17)
A18: Staff visa, medical insurance & EID (accrual) | B18: Per UAE employee | C18: =Assumptions!$F$19*Assumptions!$F$21 | D18: =Assumptions!$F$19*Assumptions!$F$21 | E18: =Assumptions!$F$19*Assumptions!$F$21 | F18: =Assumptions!$F$19*Assumptions!$F$21 | G18: =Assumptions!$F$19*Assumptions!$F$21 | H18: =Assumptions!$F$19*Assumptions!$F$21 | I18: =Assumptions!$F$19*Assumptions!$F$21 | J18: =Assumptions!$F$19*Assumptions!$F$21 | ... N18: =Assumptions!$F$19*Assumptions!$F$21 | O18: =SUM(C18:N18)
A19: End-of-service gratuity accrual | B19: 5.8% of salary | C19: =C17*Assumptions!$F$22 | D19: =D17*Assumptions!$F$22 | E19: =E17*Assumptions!$F$22 | F19: =F17*Assumptions!$F$22 | G19: =G17*Assumptions!$F$22 | H19: =H17*Assumptions!$F$22 | I19: =I17*Assumptions!$F$22 | J19: =J17*Assumptions!$F$22 | ... N19: =N17*Assumptions!$F$22 | O19: =SUM(C19:N19)
A20: WPS / payroll processing | B20: Per employee | C20: =Assumptions!$F$19*Assumptions!$F$23 | D20: =Assumptions!$F$19*Assumptions!$F$23 | E20: =Assumptions!$F$19*Assumptions!$F$23 | F20: =Assumptions!$F$19*Assumptions!$F$23 | G20: =Assumptions!$F$19*Assumptions!$F$23 | H20: =Assumptions!$F$19*Assumptions!$F$23 | I20: =Assumptions!$F$19*Assumptions!$F$23 | J20: =Assumptions!$F$19*Assumptions!$F$23 | ... N20: =Assumptions!$F$19*Assumptions!$F$23 | O20: =SUM(C20:N20)
A21: TOTAL STAFF COSTS | C21: =SUM(C16:C20) | D21: =SUM(D16:D20) | E21: =SUM(E16:E20) | F21: =SUM(F16:F20) | G21: =SUM(G16:G20) | H21: =SUM(H16:H20) | I21: =SUM(I16:I20) | J21: =SUM(J16:J20) | ... N21: =SUM(N16:N20) | O21: =SUM(C21:N21) | P21: =IF($O$86=0,0,$O21/$O$86)
A23: B. MARKETING — OPTION 1: FULLY ONLINE (switches off after M2 unless adopted)
A24: Option 1 — team cost | B24: Headcount x rate | C24: =C12*Assumptions!$F$25*Assumptions!$F$26 | D24: =D12*Assumptions!$F$25*Assumptions!$F$26 | E24: =E12*Assumptions!$F$25*Assumptions!$F$26 | F24: =F12*Assumptions!$F$25*Assumptions!$F$26 | G24: =G12*Assumptions!$F$25*Assumptions!$F$26 | H24: =H12*Assumptions!$F$25*Assumptions!$F$26 | I24: =I12*Assumptions!$F$25*Assumptions!$F$26 | J24: =J12*Assumptions!$F$25*Assumptions!$F$26 | ... N24: =N12*Assumptions!$F$25*Assumptions!$F$26 | O24: =SUM(C24:N24)
A25: Option 1 — digital ads & lead generation | C25: =C12*Assumptions!$F$27 | D25: =D12*Assumptions!$F$27 | E25: =E12*Assumptions!$F$27 | F25: =F12*Assumptions!$F$27 | G25: =G12*Assumptions!$F$27 | H25: =H12*Assumptions!$F$27 | I25: =I12*Assumptions!$F$27 | J25: =J12*Assumptions!$F$27 | ... N25: =N12*Assumptions!$F$27 | O25: =SUM(C25:N25)
A26: Option 1 — outreach tooling & CRM | C26: =C12*Assumptions!$F$28 | D26: =D12*Assumptions!$F$28 | E26: =E12*Assumptions!$F$28 | F26: =F12*Assumptions!$F$28 | G26: =G12*Assumptions!$F$28 | H26: =H12*Assumptions!$F$28 | I26: =I12*Assumptions!$F$28 | J26: =J12*Assumptions!$F$28 | ... N26: =N12*Assumptions!$F$28 | O26: =SUM(C26:N26)
A27: Option 1 — coordination & QA | C27: =C12*Assumptions!$F$29 | D27: =D12*Assumptions!$F$29 | E27: =E12*Assumptions!$F$29 | F27: =F12*Assumptions!$F$29 | G27: =G12*Assumptions!$F$29 | H27: =H12*Assumptions!$F$29 | I27: =I12*Assumptions!$F$29 | J27: =J12*Assumptions!$F$29 | ... N27: =N12*Assumptions!$F$29 | O27: =SUM(C27:N27)
A28: TOTAL — MARKETING OPTION 1 | C28: =SUM(C24:C27) | D28: =SUM(D24:D27) | E28: =SUM(E24:E27) | F28: =SUM(F24:F27) | G28: =SUM(G24:G27) | H28: =SUM(H24:H27) | I28: =SUM(I24:I27) | J28: =SUM(J24:J27) | ... N28: =SUM(N24:N27) | O28: =SUM(C28:N28) | P28: =IF($O$86=0,0,$O28/$O$86)
A30: C. MARKETING — OPTION 2: REMOTE OFFICE OUTSIDE UAE (switches off after M2 unless adopted)
A31: Option 2 — team cost | B31: Headcount x rate | C31: =C13*Assumptions!$F$31*Assumptions!$F$32 | D31: =D13*Assumptions!$F$31*Assumptions!$F$32 | E31: =E13*Assumptions!$F$31*Assumptions!$F$32 | F31: =F13*Assumptions!$F$31*Assumptions!$F$32 | G31: =G13*Assumptions!$F$31*Assumptions!$F$32 | H31: =H13*Assumptions!$F$31*Assumptions!$F$32 | I31: =I13*Assumptions!$F$31*Assumptions!$F$32 | J31: =J13*Assumptions!$F$31*Assumptions!$F$32 | ... N31: =N13*Assumptions!$F$31*Assumptions!$F$32 | O31: =SUM(C31:N31)
A32: Option 2 — coworking area rent | B32: Per HJ | C32: =C13*Assumptions!$F$33 | D32: =D13*Assumptions!$F$33 | E32: =E13*Assumptions!$F$33 | F32: =F13*Assumptions!$F$33 | G32: =G13*Assumptions!$F$33 | H32: =H13*Assumptions!$F$33 | I32: =I13*Assumptions!$F$33 | J32: =J13*Assumptions!$F$33 | ... N32: =N13*Assumptions!$F$33 | O32: =SUM(C32:N32)
A33: Option 2 — local internet, utilities & equipment | B33: Added by Claude | C33: =C13*Assumptions!$F$34 | D33: =D13*Assumptions!$F$34 | E33: =E13*Assumptions!$F$34 | F33: =F13*Assumptions!$F$34 | G33: =G13*Assumptions!$F$34 | H33: =H13*Assumptions!$F$34 | I33: =I13*Assumptions!$F$34 | J33: =J13*Assumptions!$F$34 | ... N33: =N13*Assumptions!$F$34 | O33: =SUM(C33:N33)
A34: Option 2 — on-site supervisor / team lead | B34: Added by Claude | C34: =C13*Assumptions!$F$35 | D34: =D13*Assumptions!$F$35 | E34: =E13*Assumptions!$F$35 | F34: =F13*Assumptions!$F$35 | G34: =G13*Assumptions!$F$35 | H34: =H13*Assumptions!$F$35 | I34: =I13*Assumptions!$F$35 | J34: =J13*Assumptions!$F$35 | ... N34: =N13*Assumptions!$F$35 | O34: =SUM(C34:N34)
A35: Option 2 — digital ads & lead generation | C35: =C13*Assumptions!$F$36 | D35: =D13*Assumptions!$F$36 | E35: =E13*Assumptions!$F$36 | F35: =F13*Assumptions!$F$36 | G35: =G13*Assumptions!$F$36 | H35: =H13*Assumptions!$F$36 | I35: =I13*Assumptions!$F$36 | J35: =J13*Assumptions!$F$36 | ... N35: =N13*Assumptions!$F$36 | O35: =SUM(C35:N35)
A36: Option 2 — offshore contracting / compliance | B36: Added by Claude | C36: =C13*Assumptions!$F$37 | D36: =D13*Assumptions!$F$37 | E36: =E13*Assumptions!$F$37 | F36: =F13*Assumptions!$F$37 | G36: =G13*Assumptions!$F$37 | H36: =H13*Assumptions!$F$37 | I36: =I13*Assumptions!$F$37 | J36: =J13*Assumptions!$F$37 | ... N36: =N13*Assumptions!$F$37 | O36: =SUM(C36:N36)
A37: TOTAL — MARKETING OPTION 2 | C37: =SUM(C31:C36) | D37: =SUM(D31:D36) | E37: =SUM(E31:E36) | F37: =SUM(F31:F36) | G37: =SUM(G31:G36) | H37: =SUM(H31:H36) | I37: =SUM(I31:I36) | J37: =SUM(J31:J36) | ... N37: =SUM(N31:N36) | O37: =SUM(C37:N37) | P37: =IF($O$86=0,0,$O37/$O$86)
A39: D. UNIT-ACQUISITION COMMISSION — the 2% per HJ, ongoing
A40: Trailing commission on signed units (2%) | B40: 2% of live units' revenue, every month | C40: =IF(Assumptions!$F$40=1,C10,C11)*Assumptions!$F$39 | D40: =IF(Assumptions!$F$40=1,D10,D11)*Assumptions!$F$39 | E40: =IF(Assumptions!$F$40=1,E10,E11)*Assumptions!$F$39 | F40: =IF(Assumptions!$F$40=1,F10,F11)*Assumptions!$F$39 | G40: =IF(Assumptions!$F$40=1,G10,G11)*Assumptions!$F$39 | H40: =IF(Assumptions!$F$40=1,H10,H11)*Assumptions!$F$39 | I40: =IF(Assumptions!$F$40=1,I10,I11)*Assumptions!$F$39 | J40: =IF(Assumptions!$F$40=1,J10,J11)*Assumptions!$F$39 | ... N40: =IF(Assumptions!$F$40=1,N10,N11)*Assumptions!$F$39 | O40: =SUM(C40:N40)
A41: TOTAL COMMISSION | C41: =SUM(C40:C40) | D41: =SUM(D40:D40) | E41: =SUM(E40:E40) | F41: =SUM(F40:F40) | G41: =SUM(G40:G40) | H41: =SUM(H40:H40) | I41: =SUM(I40:I40) | J41: =SUM(J40:J40) | ... N41: =SUM(N40:N40) | O41: =SUM(C41:N41) | P41: =IF($O$86=0,0,$O41/$O$86)
A43: E. TECHNOLOGY, PLATFORM & AI
A44: PMS / channel manager licence | B44: Per live unit | C44: =C9*Assumptions!$F$42 | D44: =D9*Assumptions!$F$42 | E44: =E9*Assumptions!$F$42 | F44: =F9*Assumptions!$F$42 | G44: =G9*Assumptions!$F$42 | H44: =H9*Assumptions!$F$42 | I44: =I9*Assumptions!$F$42 | J44: =J9*Assumptions!$F$42 | ... N44: =N9*Assumptions!$F$42 | O44: =SUM(C44:N44)
A45: Dynamic pricing tool | B45: Per live unit | C45: =C9*Assumptions!$F$43 | D45: =D9*Assumptions!$F$43 | E45: =E9*Assumptions!$F$43 | F45: =F9*Assumptions!$F$43 | G45: =G9*Assumptions!$F$43 | H45: =H9*Assumptions!$F$43 | I45: =I9*Assumptions!$F$43 | J45: =J9*Assumptions!$F$43 | ... N45: =N9*Assumptions!$F$43 | O45: =SUM(C45:N45)
A46: Smart-lock / access platform | B46: Per live unit | C46: =C9*Assumptions!$F$44 | D46: =D9*Assumptions!$F$44 | E46: =E9*Assumptions!$F$44 | F46: =F9*Assumptions!$F$44 | G46: =G9*Assumptions!$F$44 | H46: =H9*Assumptions!$F$44 | I46: =I9*Assumptions!$F$44 | J46: =J9*Assumptions!$F$44 | ... N46: =N9*Assumptions!$F$44 | O46: =SUM(C46:N46)
...

Sheet Marketing Comparison
A1: MARKETING OPTION 1 vs OPTION 2 — THE MONTH-3 DECISION
A2: Both options run in parallel for Months 1–2 per HJ. This tab is what you use to pick one.
A4: HEAD-TO-HEAD, STEADY-STATE MONTHLY COST
A5: Component | B5: Option 1 — Fully online | C5: Option 2 — Remote office | D5: Difference | G5: Comment
A6: Team cost | B6: =Assumptions!$F$25*Assumptions!$F$26 | C6: =Assumptions!$F$31*Assumptions!$F$32 | D6: =B6-C6 | G6: Option 2 buys roughly double the headcount for less money — offshore rates outside the UAE.
A7: Coworking / premises rent | B7: =0 | C7: =Assumptions!$F$33 | D7: =B7-C7 | G7: Option 1 has no premises. This is the single line that erodes Option 2's labour-cost advantage.
A8: Local internet, utilities & equipment | B8: =0 | C8: =Assumptions!$F$34 | D8: =B8-C8 | G8: Physical office overhead.
A9: On-site supervisor / team lead | B9: =Assumptions!$F$29 | C9: =Assumptions!$F$35 | D9: =B9-C9 | G9: Option 1 needs light remote QA; Option 2 needs someone in the room.
A10: Digital ads & lead generation | B10: =Assumptions!$F$27 | C10: =Assumptions!$F$36 | D10: =B10-C10 | G10: Option 1 leans on paid leads; Option 2 leans on manual prospecting volume.
A11: Outreach tooling & CRM | B11: =Assumptions!$F$28 | C11: =0 | D11: =B11-C11 | G11: Option 1 is tooling-dependent by design.
A12: Offshore contracting / compliance | B12: =0 | C12: =Assumptions!$F$37 | D12: =B12-C12 | G12: Engaging staff outside the UAE needs a compliant route. Not in the original brief — flagged, not hidden.
A13: TOTAL FIXED MONTHLY COST | B13: =SUM(B6:B12) | C13: =SUM(C6:C12) | D13: =SUM(D6:D12)
A14: Headcount | B14: =Assumptions!$F$25 | C14: =Assumptions!$F$31 | D14: =B14-C14 | G14: Both at 4 hours per day per HJ.
A15: Cost per head | B15: =IF(B14=0,0,B13/B14) | C15: =IF(C14=0,0,C13/C14) | D15: =B15-C15 | G15: All-in cost of one working person, including their share of premises and tooling. This is the number that actually decides it.
A17: BREAK-EVEN — how many units must each option sign to pay for itself?
A18: Orizuru revenue per live unit per month | B18: =Assumptions!$F$16 | G18: From the Assumptions tab.
A19: Units needed to cover the option's fixed cost | B19: =IF($B$18=0,0,B13/$B$18) | C19: =IF($B$18=0,0,C13/$B$18) | G19: Each option only has to sign this many units to wash its own face. Both numbers are small — which is why running both for two months is a cheap experiment, not a risk.
A21: COST OF THE 2-MONTH PARALLEL RUN
A22: Both options, Months 1–2 combined | B22: =(B13+C13)*Assumptions!$B$7 | G22: The total price of the experiment HJ described.
A23: Incremental cost vs running the cheaper option alone | B23: =(MAX(B13,C13))*Assumptions!$B$7 | G23: What the second option costs you on top. Judge the experiment against this, not the gross figure.
A24: Units the experiment must produce to justify itself | B24: =IF($B$18=0,0,B23/$B$18) | G24: If the losing option signs at least this many units in two months, the experiment paid for itself regardless of which one you keep.
A26: WHAT TO MEASURE BEFORE YOU DECIDE IN MONTH 3
A27: • Units signed per option — the only metric that ultimately matters.
A28: • Cost per signed unit = the option's 2-month cost / units it signed. Compare directly.
A29: • Owner meetings booked per person per week — tells you whether the difference is effort or conversion.
A30: • Lead-to-meeting and meeting-to-signature conversion rates, tracked separately per option.
A31: • Quality of units signed: a team that signs cheap studios in weak buildings is not outperforming.
A32: • Attrition and reliability — Option 2's larger offshore team carries more people risk.
A33: • Language and time-zone fit with Dubai property owners. Under-weighted and it decides more deals than price does.
A35: READ-ACROSS
A36: • Option 2 typically wins on raw cost per head even after paying coworking rent, because it buys 4–6 people for roughly what 2–4 cost online. Its risk is not cost — it is supervision and consistency.
A37: • Option 1's real cost is the ads budget, not the salaries. Strip the ad spend out and it looks cheap, but a fully-online team with no lead flow signs nothing.
A38: • The 2% trailing commission applies identically to both options, so it does not affect the choice — but it does mean marketing cost keeps growing with the portfolio long after the team is fixed. See the OPEX Monthly tab.
A39: • Whatever you choose, the decision should be made on cost per SIGNED UNIT, not on total spend.

Sheet AI Subscriptions
A1: AI SUBSCRIPTIONS — DETAIL
A2: HJ item 5. Feeds the 'AI subscriptions' line in the OPEX model. USD converted at the pegged AED rate.
A4: USD/AED peg | B4: 3.6725 | C4: AED is pegged to USD at 3.6725. Fixed, so no FX risk on these subscriptions.
A6: Tool | B6: Plan | C6: Seats | D6: Price/seat (USD, monthly) | E6: Monthly cost (AED) | F6: Annual cost (AED) | G6: What it does for Orizuru
A7: Claude | B7: Max (5x) | C7: 1 | D7: 100 | E7: =C7*D7*$B$4 | F7: =E7*12 | G7: Core workhorse: owner proposals, management contracts, DET compliance drafting, financial reporting, guest-comms tone-of-voice.
A8: Claude | B8: Pro | C8: 2 | D8: 20 | E8: =C8*D8*$B$4 | F8: =E8*12 | G8: Seats for the operations staff member and the marketing team lead.
A9: ChatGPT | B9: Business | C9: 2 | D9: 25 | E9: =C9*D9*$B$4 | F9: =E9*12 | G9: Second-opinion model plus image generation for listing and social content.
A10: Google Gemini | B10: AI Pro (via Workspace) | C10: 2 | D10: 20 | E10: =C10*D10*$B$4 | F10: =E10*12 | G10: Long-context document review and Sheets/Docs automation for owner reporting.
A11: Perplexity | B11: Pro | C11: 1 | D11: 20 | E11: =C11*D11*$B$4 | F11: =E11*12 | G11: Live comparable-rate research: what competing units in the same tower are charging tonight.
A12: Canva | B12: Pro / Teams | C12: 2 | D12: 15 | E12: =C12*D12*$B$4 | F12: =E12*12 | G12: Listing graphics, owner pitch decks, social content at volume without a designer.
A13: PMS AI guest-messaging add-on | B13: Per-property tier | C13: 1 | D13: 49 | E13: =C13*D13*$B$4 | F13: =E13*12 | G13: Auto-responds to routine guest questions 24/7. Directly supports the 24/7 support promise in the Business Profile.
A14: AI transcription / meeting notes | B14: Standard | C14: 1 | D14: 18 | E14: =C14*D14*$B$4 | F14: =E14*12 | G14: Owner calls and site visits captured without manual note-taking.
A15: Buffer / social scheduling with AI | B15: Team | C15: 1 | D15: 12 | E15: =C15*D15*$B$4 | F15: =E15*12 | G15: Schedules the marketing team's output across channels.
A16: TOTAL — AI SUBSCRIPTIONS | E16: =SUM(E7:E15) | F16: =SUM(F7:F15)
A18: This is the Base case. In the OPEX model, the Low case assumes a trimmed stack (Claude Max + one assistant seat only) and the High case assumes the full stack plus additional seats as the marketing team scales. Edit seats and prices above and the Base figure flows straight through.
