Workbook

Sheet README
A1: ORIZURU HOLIDAY HOMES LLC — CAPITAL EXPENDITURE (CAPEX)
A2: Dubai, UAE | Trade Licence 1634278 | All figures in AED
A5: HOW TO USE THIS WORKBOOK
A6: Tab | B6: What it contains
A7: CAPEX Detail | B7: Every one-off setup cost, line by line, at Low / Base / High. This is the main sheet.
A8: Unit Setup (1 Unit) | B8: Cost to bring ONE holiday-home unit live, plus a scaling table (x1 to x80).
A9: CAPEX Summary | B9: Category roll-up and funding view. Reads from the two sheets above.
A11: MODEL BASIS — CONFIRMED WITH HJ
A12: 1. | B12: Pure management / commission-only model. Orizuru does NOT master-lease units, so there is NO unit rent, DEWA deposit or furnishing capex per unit — those sit with the property owner.
A13: 2. | B13: Unit setup CAPEX is sized for ONE unit only. The scaling table on 'Unit Setup' shows the cost if the portfolio is rolled out to 5 / 10 / 25 / 50 / 80 units, but nothing is scaled by default.
A14: 3. | B14: The AED 2,000,000 shareholder capital in the Business Profile is NOT used as a target or a cap. This CAPEX is built bottom-up from what the business actually needs.
A15: 4. | B15: Directors draw no salary. See the OPEX workbook.
A17: COLOUR LEGEND
A18: Blue text | B18: Hardcoded input — edit these freely.
A19: Yellow fill | B19: Key assumption or a figure you supplied. Check before circulating.
A20: Black text | B20: Formula. Do not overwrite.
A21: Green text | B21: Link to another sheet in this workbook.
A23: FIGURES SUPPLIED BY HJ (used as-is, not estimated)
A24: • | B24: Domain name, 3 years — AED 387
A25: • | B25: Company stamp — AED 137
A27: IMPORTANT NOTES
A28: • | B28: Bank minimum balance is shown as a MEMO item, not CAPEX. It is a blocked asset, not a cost — do not add it to the CAPEX total when presenting to the bank.
A29: • | B29: Company formation costs dated on or before 03/07/2026 are likely already incurred. Mark them in the 'Status' column so the sheet distinguishes sunk cost from cash still to be spent.
A30: • | B30: DET (formerly DTCM) holiday-home permit fees are charged per unit per year and are re-charged to the owner in most Dubai management contracts. First issue sits in CAPEX; renewals sit in OPEX.
A31: • | B31: Contingency is set at 10% of subtotal. Standard for a first-year UAE service company where licensing and regulatory fees move.

Sheet CAPEX Summary
A1: CAPEX SUMMARY BY CATEGORY
A2: All figures AED. Base case is the presentation figure; Low / High frame the range.
A4: Category | B4: Low | C4: Base | D4: High | E4: % of Base total | F4: Comment
A5: A. COMPANY FORMATION, LICENSING & REGULATORY | B5: ='CAPEX Detail'!G45 | C5: ='CAPEX Detail'!H45 | D5: ='CAPEX Detail'!I45 | E5: =IF($C$12=0,0,C5/$C$12) | F5: Largely fixed and largely unavoidable. Most of it is already incurred as at 03/07/2026.
A6: B. TECHNOLOGY, PLATFORM & DIGITAL SETUP | B6: ='CAPEX Detail'!G46 | C6: ='CAPEX Detail'!H46 | D6: ='CAPEX Detail'!I46 | E6: =IF($C$12=0,0,C6/$C$12) | F6: The direct booking engine is the highest-return line in the whole CAPEX — it removes OTA commission on repeat guests.
A7: C. BRAND & MARKETING SETUP | B7: ='CAPEX Detail'!G47 | C7: ='CAPEX Detail'!H47 | D7: ='CAPEX Detail'!I47 | E7: =IF($C$12=0,0,C7/$C$12) | F7: Directly enables both marketing options. The owner pitch deck is what the acquisition team actually sells with.
A8: D. OFFICE EQUIPMENT & FURNITURE (DUBAI) | B8: ='CAPEX Detail'!G48 | C8: ='CAPEX Detail'!H48 | D8: ='CAPEX Detail'!I48 | E8: =IF($C$12=0,0,C8/$C$12) | F8: Scale-insensitive. Same cost at 1 unit or 80.
A9: E. DEPOSITS & PREPAYMENTS | B9: ='CAPEX Detail'!G49 | C9: ='CAPEX Detail'!H49 | D9: ='CAPEX Detail'!I49 | E9: =IF($C$12=0,0,C9/$C$12) | F9: Mostly refundable. Cash timing rather than true cost.
A10: Unit setup — 1 unit | B10: ='CAPEX Detail'!G51 | C10: ='CAPEX Detail'!H51 | D10: ='CAPEX Detail'!I51 | E10: =IF($C$12=0,0,C10/$C$12) | F10: Per HJ: one unit only. Multiply on the 'Unit Setup' tab for portfolio scale.
A11: Contingency | B11: ='CAPEX Detail'!G52 | C11: ='CAPEX Detail'!H52 | D11: ='CAPEX Detail'!I52 | E11: =IF($C$12=0,0,C11/$C$12) | F11: 10% of company-setup subtotal.
A12: TOTAL CAPEX | B12: =SUM(B5:B11) | C12: =SUM(C5:C11) | D12: =SUM(D5:D11) | E12: =IF($C$12=0,0,SUM(E5:E11))
A15: READ-ACROSS
A16: • The Business Profile states AED 2,000,000 of shareholder capital. Per HJ this CAPEX is NOT sized to that number — it is built bottom-up from what the business needs, and the balance is available as working capital and runway.
A17: • Because Orizuru operates commission-only, CAPEX is genuinely light: there is no furniture, no unit deposits and no master-lease prepayment. The heavy spend in this business is OPEX, not CAPEX.
A18: • The single largest scaling risk is NOT in this workbook: it is the per-unit setup cost multiplied out. At the Business Profile's 70–80 unit target the unit-setup line alone becomes material — see the scaling table on the 'Unit Setup' tab.
A19: • Refundable items (office deposit, DEWA deposit, labour guarantee) are inside the total. Strip them out if presenting a 'true sunk cost' figure.

Sheet CAPEX Detail
A1: CAPEX DETAIL — ONE-OFF SETUP EXPENDITURE
A2: Company formation, licensing, technology, brand and equipment. Unit setup is on the 'Unit Setup (1 Unit)' tab.
A4: Ref | B4: Line item | C4: Qty | D4: Unit cost — Low | E4: Unit cost — Base | F4: Unit cost — High | G4: Total — Low | H4: Total — Base | I4: Total — High | J4: Timing / status | K4: Basis / note
A5: A. COMPANY FORMATION, LICENSING & REGULATORY
A6: A1 | B6: DED trade licence — initial issue (Vacation Homes Rental) | C6: 1 | D6: 13500 | E6: 17500 | F6: 22000 | G6: =$C6*D6 | H6: =$C6*E6 | I6: =$C6*F6 | J6: Incurred — 03/07/2026 | K6: Mainland LLC commercial licence. Licence No. 1634278 per the Business Profile.
A7: A2 | B7: Trade name reservation & initial approval | C7: 1 | D7: 900 | E7: 1200 | F7: 1600 | G7: =$C7*D7 | H7: =$C7*E7 | I7: =$C7*F7 | J7: Incurred — 03/07/2026 | K7: DED fixed fees.
A8: A3 | B8: MOA drafting & notarisation | C8: 1 | D8: 1800 | E8: 2500 | F8: 3500 | G8: =$C8*D8 | H8: =$C8*E8 | I8: =$C8*F8 | J8: Incurred — 03/07/2026 | K8: Three-shareholder structure per the Business Profile (Podocarpus 70% / Atayev 16% / Mamiyev 14%).
A9: A4 | B9: Ejari / tenancy registration for the licensed address | C9: 1 | D9: 1500 | E9: 2200 | F9: 3200 | G9: =$C9*D9 | H9: =$C9*E9 | I9: =$C9*F9 | J9: Incurred — 03/07/2026 | K9: Fronds Building – Office 02, Goze Industrial Third. Required to hold the licence.
A10: A5 | B10: Immigration establishment card | C10: 1 | D10: 1000 | E10: 1500 | F10: 2200 | G10: =$C10*D10 | H10: =$C10*E10 | I10: =$C10*F10 | J10: Month 1 | K10: Required before any employment visa can be issued.
A11: A6 | B11: MOHRE labour file / e-Channel registration | C11: 1 | D11: 1600 | E11: 2300 | F11: 3200 | G11: =$C11*D11 | H11: =$C11*E11 | I11: =$C11*F11 | J11: Month 1 | K11: Needed to sponsor the operations & service staff member.
A12: A7 | B12: DET (ex-DTCM) holiday-home OPERATOR permit — company level | C12: 1 | D12: 4500 | E12: 7500 | F12: 12000 | G12: =$C12*D12 | H12: =$C12*E12 | I12: =$C12*F12 | J12: Month 1 | K12: Distinct from the per-unit permit. Without it the company cannot legally list short-term rentals.
A13: A8 | B13: Corporate bank account opening & KYC pack | C13: 1 | D13: 0 | E13: 500 | F13: 1500 | G13: =$C13*D13 | H13: =$C13*E13 | I13: =$C13*F13 | J13: Month 1 | K13: Corporate current account, multi-currency AED/USD/EUR per the Business Profile.
A14: A9 | B14: VAT registration & Corporate Tax registration | C14: 1 | D14: 0 | E14: 1000 | F14: 2500 | G14: =$C14*D14 | H14: =$C14*E14 | I14: =$C14*F14 | J14: Incurred | K14: TRN 105507385000001 already issued per the Business Profile. Cost shown for completeness.
A15: A10 | B15: Company stamp | C15: 1 | D15: 137 | E15: 137 | F15: 137 | G15: =$C15*D15 | H15: =$C15*E15 | I15: =$C15*F15 | J15: Incurred | K15: Actual figure supplied by HJ — AED 137.
A16: A11 | B16: Employment visa — operations & service staff (1 person) | C16: 1 | D16: 4500 | E16: 6000 | F16: 8000 | G16: =$C16*D16 | H16: =$C16*E16 | I16: =$C16*F16 | J16: Month 1 | K16: Entry permit, status change, medical, Emirates ID, 2-year residence visa.
A17: A12 | B17: Refundable labour guarantee / bank guarantee (1 employee) | C17: 1 | D17: 0 | E17: 3000 | F17: 3000 | G17: =$C17*D17 | H17: =$C17*E17 | I17: =$C17*F17 | J17: Month 1 | K17: MOHRE requirement. Refundable, but cash out on day one.
A18: B. TECHNOLOGY, PLATFORM & DIGITAL SETUP
A19: B1 | B19: Domain name registration — 3 years | C19: 1 | D19: 387 | E19: 387 | F19: 387 | G19: =$C19*D19 | H19: =$C19*E19 | I19: =$C19*F19 | J19: Incurred | K19: Actual figure supplied by HJ — AED 387 for 3 years.
A20: B2 | B20: Website build + direct booking engine | C20: 1 | D20: 7000 | E20: 12000 | F20: 22000 | G20: =$C20*D20 | H20: =$C20*E20 | I20: =$C20*F20 | J20: Month 1–2 | K20: The Business Profile commits to a direct booking portal. Direct bookings avoid the 15–18% OTA commission, so this pays back fastest of any line here.
A21: B3 | B21: PMS / channel manager onboarding & setup fee (Hostaway, Guesty or equivalent) | C21: 1 | D21: 1800 | E21: 3000 | F21: 5500 | G21: =$C21*D21 | H21: =$C21*E21 | I21: =$C21*F21 | J21: Month 1 | K21: One-off implementation. The recurring per-unit licence sits in OPEX.
A22: B4 | B22: Channel account setup & verification (Airbnb, Booking.com, direct) | C22: 1 | D22: 0 | E22: 800 | F22: 1800 | G22: =$C22*D22 | H22: =$C22*E22 | I22: =$C22*F22 | J22: Month 1 | K22: Account verification, payout setup, listing template build.
A23: B5 | B23: Business email, Google Workspace & cloud drive setup | C23: 1 | D23: 300 | E23: 600 | F23: 1200 | G23: =$C23*D23 | H23: =$C23*E23 | I23: =$C23*F23 | J23: Month 1 | K23: One-off configuration. Seat licences are OPEX.
A24: B6 | B24: Accounting system setup & chart of accounts (Zoho Books / Xero) | C24: 1 | D24: 800 | E24: 1500 | F24: 3000 | G24: =$C24*D24 | H24: =$C24*E24 | I24: =$C24*F24 | J24: Month 1 | K24: VAT-compliant chart of accounts. Doing this properly now avoids a costly first-audit clean-up.
A25: B7 | B25: AI workspace setup — prompt library, SOP automation, guest-messaging templates | C25: 1 | D25: 0 | E25: 1500 | F25: 4000 | G25: =$C25*D25 | H25: =$C25*E25 | I25: =$C25*F25 | J25: Month 1–2 | K25: One-off build of the AI operating layer. The recurring subscription cost sits in OPEX per HJ item 5.
A26: C. BRAND & MARKETING SETUP
A27: C1 | B27: Brand identity — logo, typography, Japanese-inspired visual system | C27: 1 | D27: 2500 | E27: 4500 | F27: 9000 | G27: =$C27*D27 | H27: =$C27*E27 | I27: =$C27*F27 | J27: Month 1 | K27: Supports the Ma / Shibui / Bushido / Wabi-Sabi brand philosophy in the Business Profile.
A28: C2 | B28: Brand photography & short-form video (company level, not per unit) | C28: 1 | D28: 2000 | E28: 3500 | F28: 7000 | G28: =$C28*D28 | H28: =$C28*E28 | I28: =$C28*F28 | J28: Month 1–2 | K28: Used across the website, OTA profile and owner pitch deck.
A29: C3 | B29: Owner acquisition pitch deck & management-contract pack | C29: 1 | D29: 800 | E29: 1800 | F29: 3500 | G29: =$C29*D29 | H29: =$C29*E29 | I29: =$C29*F29 | J29: Month 1 | K29: The core sales asset for the marketing team in both Option 1 and Option 2.
A30: C4 | B30: Printed collateral, business cards, owner welcome pack | C30: 1 | D30: 400 | E30: 900 | F30: 1800 | G30: =$C30*D30 | H30: =$C30*E30 | I30: =$C30*F30 | J30: Month 1
A31: C5 | B31: Social media profile setup & launch content batch | C31: 1 | D31: 500 | E31: 1200 | F31: 2500 | G31: =$C31*D31 | H31: =$C31*E31 | I31: =$C31*F31 | J31: Month 1
A32: D. OFFICE EQUIPMENT & FURNITURE (DUBAI)
A33: D1 | B33: Laptop — operations | C33: 2 | D33: 2800 | E33: 3800 | F33: 5500 | G33: =$C33*D33 | H33: =$C33*E33 | I33: =$C33*F33 | J33: Month 1 | K33: One for the operations & service staff member, one for management.
A34: D2 | B34: Mobile handset — dedicated 24/7 guest support line | C34: 1 | D34: 1200 | E34: 1900 | F34: 3200 | G34: =$C34*D34 | H34: =$C34*E34 | I34: =$C34*F34 | J34: Month 1 | K34: The Business Profile promises 24/7 guest support. It needs its own line and device.
A35: D3 | B35: Printer / scanner (contracts, DET paperwork) | C35: 1 | D35: 500 | E35: 850 | F35: 1500 | G35: =$C35*D35 | H35: =$C35*E35 | I35: =$C35*F35 | J35: Month 1
A36: D4 | B36: Office desk, chairs & storage | C36: 1 | D36: 1800 | E36: 3200 | F36: 6000 | G36: =$C36*D36 | H36: =$C36*E36 | I36: =$C36*F36 | J36: Month 1
A37: D5 | B37: Key-safe cabinet & spare-key management system | C37: 1 | D37: 500 | E37: 900 | F37: 1600 | G37: =$C37*D37 | H37: =$C37*E37 | I37: =$C37*F37 | J37: Month 1 | K37: Physical key control across a multi-unit portfolio. An audit point for owners.
A38: D6 | B38: Router, networking & basic office IT | C38: 1 | D38: 300 | E38: 550 | F38: 1000 | G38: =$C38*D38 | H38: =$C38*E38 | I38: =$C38*F38 | J38: Month 1
A39: E. DEPOSITS & PREPAYMENTS
A40: E1 | B40: Office rent security deposit (refundable) | C40: 1 | D40: 2500 | E40: 5000 | F40: 9000 | G40: =$C40*D40 | H40: =$C40*E40 | I40: =$C40*F40 | J40: Month 1 | K40: Refundable at lease end. Cash out on day one.
A41: E2 | B41: DEWA office connection deposit (refundable) | C41: 1 | D41: 1000 | E41: 2000 | F41: 3500 | G41: =$C41*D41 | H41: =$C41*E41 | I41: =$C41*F41 | J41: Month 1 | K41: Refundable.
...

Sheet Unit Setup (1 Unit)
A1: UNIT SETUP CAPEX — COST TO BRING ONE UNIT LIVE
A2: Commission-only model: the owner supplies the furnished apartment. Orizuru funds only the operating layer.
A4: Ref | B4: Line item | C4: Qty | D4: Unit cost — Low | E4: Unit cost — Base | F4: Unit cost — High | G4: Total — Base | H4: Basis / note
A5: U1 | B5: DET holiday-home permit — first issue (per unit, per year) | C5: 1 | D5: 1200 | E5: 1520 | F5: 1800 | G5: =C5*E5 | H5: Dubai Dept. of Economy & Tourism per-unit permit. Usually re-charged to the owner — confirm in the management contract.
A6: U2 | B6: Smart lock / keyless entry device + install | C6: 1 | D6: 850 | E6: 1200 | F6: 1700 | G6: =C6*E6 | H6: Essential for self check-in. Removes the cost of a physical key handover per booking.
A7: U3 | B7: Professional listing photography (unit) | C7: 1 | D7: 500 | E7: 800 | F7: 1400 | G7: =C7*E7 | H7: Single biggest driver of conversion on Airbnb / Booking.com. Do not economise here.
A8: U4 | B8: Linen & towel par stock — 3 sets | C8: 1 | D8: 1100 | E8: 1800 | F8: 2600 | G8: =C8*E8 | H8: 3 sets allows one in use, one in laundry, one on the shelf. Required for same-day turnovers.
A9: U5 | B9: Welcome & amenity kit (branded, Japanese-hospitality standard) | C9: 1 | D9: 300 | E9: 450 | F9: 700 | G9: =C9*E9 | H9: Brand differentiator per the Ma / Shibui positioning in the Business Profile.
A10: U6 | B10: Safety kit — smoke detector, fire extinguisher, first-aid box | C10: 1 | D10: 380 | E10: 550 | F10: 800 | G10: =C10*E10 | H10: DET holiday-home inspection requirement.
A11: U7 | B11: Small appliances & inventory top-up (kettle, iron, hairdryer, crockery gaps) | C11: 1 | D11: 500 | E11: 900 | F11: 1600 | G11: =C11*E11 | H11: Covers the gap between what the owner supplies and DET / guest expectation.
A12: U8 | B12: Initial deep clean & staging before first listing | C12: 1 | D12: 400 | E12: 600 | F12: 950 | G12: =C12*E12 | H12: One-off. Routine turnover cleaning sits in OPEX.
A13: U9 | B13: Inventory & condition report, listing build, channel sync | C13: 1 | D13: 200 | E13: 300 | F13: 500 | G13: =C13*E13 | H13: Protects against damage disputes and is the baseline for owner reporting.
A14: U10 | B14: Guest welcome book, house rules, signage (printed) | C14: 1 | D14: 120 | E14: 200 | F14: 350 | G14: =C14*E14 | H14: Reduces avoidable guest-support contacts.
B15: Subtotal — per unit | D15: =SUMPRODUCT($C$5:$C$14,D5:D14) | E15: =SUMPRODUCT($C$5:$C$14,E5:E14) | F15: =SUMPRODUCT($C$5:$C$14,F5:F14) | G15: =SUM(G5:G14)
B16: Contingency | C16: 0.1 | D16: =D15*$C$16 | E16: =E15*$C$16 | F16: =F15*$C$16 | G16: =G15*$C$16 | H16: Applied to the per-unit subtotal. Covers price movement on permits and hardware.
B17: TOTAL CAPEX PER UNIT | D17: =D15+D16 | E17: =E15+E16 | F17: =F15+F16 | G17: =G15+G16
A20: PORTFOLIO SCALING REFERENCE — FOR INFORMATION ONLY, NOT INCLUDED IN THE CAPEX TOTAL
A21: Per HJ, the CAPEX total is built for ONE unit. This table shows what the same unit-setup cost becomes at portfolio scale, against the Business Profile's 70–80 unit Year-1 target.
A23: Units | B23: Total — Low | C23: Total — Base | D23: Total — High
A24: 1 | B24: =$A24*D$17 | C24: =$A24*E$17 | D24: =$A24*F$17
A25: 5 | B25: =$A25*D$17 | C25: =$A25*E$17 | D25: =$A25*F$17
A26: 10 | B26: =$A26*D$17 | C26: =$A26*E$17 | D26: =$A26*F$17
A27: 25 | B27: =$A27*D$17 | C27: =$A27*E$17 | D27: =$A27*F$17
A28: 50 | B28: =$A28*D$17 | C28: =$A28*E$17 | D28: =$A28*F$17
A29: 80 | B29: =$A29*D$17 | C29: =$A29*E$17 | D29: =$A29*F$17
